Workbook

Sheet SINTESI
A1: SINTESI DELLO SCREENING
A2: Un foglio per mercato. Le soglie stanno in PARAMETRI: cambiale li' e tutti i giudizi si ricalcolano.
A4: Esito | B4: Titoli
A5: PASSA FORTE | B5: =COUNTIF('ITALIA'!AG2:AG67,"PASSA FORTE")+COUNTIF('GERMANIA'!AG2:AG44,"PASSA FORTE")+COUNTIF('FRANCIA'!AG2:AG36,"PASSA FORTE")+COUNTIF('PAESI BASSI'!AG2:AG21,"PASSA FORTE")+COUNTIF('SVIZZERA'!AG2:AG24,"PASSA FORTE")+COUNTIF('USA'!AG2:AG167,"PASSA FORTE")
A6: PASSA | B6: =COUNTIF('ITALIA'!AG2:AG67,"PASSA")+COUNTIF('GERMANIA'!AG2:AG44,"PASSA")+COUNTIF('FRANCIA'!AG2:AG36,"PASSA")+COUNTIF('PAESI BASSI'!AG2:AG21,"PASSA")+COUNTIF('SVIZZERA'!AG2:AG24,"PASSA")+COUNTIF('USA'!AG2:AG167,"PASSA")
A7: SCARTA | B7: =COUNTIF('ITALIA'!AG2:AG67,"SCARTA")+COUNTIF('GERMANIA'!AG2:AG44,"SCARTA")+COUNTIF('FRANCIA'!AG2:AG36,"SCARTA")+COUNTIF('PAESI BASSI'!AG2:AG21,"SCARTA")+COUNTIF('SVIZZERA'!AG2:AG24,"SCARTA")+COUNTIF('USA'!AG2:AG167,"SCARTA")
A8: DA COMPLETARE | B8: =COUNTIF('ITALIA'!AG2:AG67,"DA COMPLETARE")+COUNTIF('GERMANIA'!AG2:AG44,"DA COMPLETARE")+COUNTIF('FRANCIA'!AG2:AG36,"DA COMPLETARE")+COUNTIF('PAESI BASSI'!AG2:AG21,"DA COMPLETARE")+COUNTIF('SVIZZERA'!AG2:AG24,"DA COMPLETARE")+COUNTIF('USA'!AG2:AG167,"DA COMPLETARE")
A9: Totale | B9: =SUM(B5:B8)
A11: Per mercato
A12: Mercato | B12: Titoli | C12: Passano | D12: P/E medio | E12: Punteggio medio
A13: Italia | B13: =COUNTA('ITALIA'!B2:B67) | C13: =COUNTIF('ITALIA'!AG2:AG67,"PASSA")+COUNTIF('ITALIA'!AG2:AG67,"PASSA FORTE") | D13: =IFERROR(AVERAGE('ITALIA'!M2:M67),"") | E13: =IFERROR(AVERAGE('ITALIA'!AD2:AD67),"")
A14: Germania | B14: =COUNTA('GERMANIA'!B2:B44) | C14: =COUNTIF('GERMANIA'!AG2:AG44,"PASSA")+COUNTIF('GERMANIA'!AG2:AG44,"PASSA FORTE") | D14: =IFERROR(AVERAGE('GERMANIA'!M2:M44),"") | E14: =IFERROR(AVERAGE('GERMANIA'!AD2:AD44),"")
A15: Francia | B15: =COUNTA('FRANCIA'!B2:B36) | C15: =COUNTIF('FRANCIA'!AG2:AG36,"PASSA")+COUNTIF('FRANCIA'!AG2:AG36,"PASSA FORTE") | D15: =IFERROR(AVERAGE('FRANCIA'!M2:M36),"") | E15: =IFERROR(AVERAGE('FRANCIA'!AD2:AD36),"")
A16: Paesi Bassi | B16: =COUNTA('PAESI BASSI'!B2:B21) | C16: =COUNTIF('PAESI BASSI'!AG2:AG21,"PASSA")+COUNTIF('PAESI BASSI'!AG2:AG21,"PASSA FORTE") | D16: =IFERROR(AVERAGE('PAESI BASSI'!M2:M21),"") | E16: =IFERROR(AVERAGE('PAESI BASSI'!AD2:AD21),"")
A17: Svizzera | B17: =COUNTA('SVIZZERA'!B2:B24) | C17: =COUNTIF('SVIZZERA'!AG2:AG24,"PASSA")+COUNTIF('SVIZZERA'!AG2:AG24,"PASSA FORTE") | D17: =IFERROR(AVERAGE('SVIZZERA'!M2:M24),"") | E17: =IFERROR(AVERAGE('SVIZZERA'!AD2:AD24),"")
A18: USA | B18: =COUNTA('USA'!B2:B167) | C18: =COUNTIF('USA'!AG2:AG167,"PASSA")+COUNTIF('USA'!AG2:AG167,"PASSA FORTE") | D18: =IFERROR(AVERAGE('USA'!M2:M167),"") | E18: =IFERROR(AVERAGE('USA'!AD2:AD167),"")
A21: Per settore
A22: Settore | B22: Italia | C22: Germania | D22: Francia | E22: Paesi Bassi | F22: Svizzera | G22: USA | H22: Totale | I22: Passano | J22: ROE 1a medio
A23: Tecnologia | B23: =COUNTIF('ITALIA'!E2:E67,$A23) | C23: =COUNTIF('GERMANIA'!E2:E44,$A23) | D23: =COUNTIF('FRANCIA'!E2:E36,$A23) | E23: =COUNTIF('PAESI BASSI'!E2:E21,$A23) | F23: =COUNTIF('SVIZZERA'!E2:E24,$A23) | G23: =COUNTIF('USA'!E2:E167,$A23) | H23: =SUM(B23:G23) | I23: =COUNTIFS('ITALIA'!E2:E67,$A23,'ITALIA'!AG2:AG67,"PASSA")+COUNTIFS('ITALIA'!E2:E67,$A23,'ITALIA'!AG2:AG67,"PASSA FORTE")+COUNTIFS('GERMANIA'!E2:E44,$A23,'GERMANIA'!AG2:AG44,"PASSA")+COUNTIFS('GERMANIA'!E2:E44,$A23,'GERMANIA'!AG2:AG44,"PASSA FORTE")+COUNTIFS('FRANCIA'!E2:E36,$A23,'FRANCIA'!AG2:AG36,"PASSA")+COUNTIFS('FRANCIA'!E2:E36,$A23,'FRANCIA'!AG2:AG36,"PASSA FORTE")+COUNTIFS('PAESI BASSI'!E2:E21,$A23,'PAESI BASSI'!AG2:AG21,"PASSA")+COUNTIFS('PAESI BASSI'!E2:E21,$A23,'PAESI BASSI'!AG2:AG21,"PASSA FORTE")+COUNTIFS('SVIZZERA'!E2:E24,$A23,'SVIZZERA'!AG2:AG24,"PASSA")+COUNTIFS('SVIZZERA'!E2:E24,$A23,'SVIZZERA'!AG2:AG24,"PASSA FORTE")+COUNTIFS('USA'!E2:E167,$A23,'USA'!AG2:AG167,"PASSA")+COUNTIFS('USA'!E2:E167,$A23,'USA'!AG2:AG167,"PASSA FORTE") | J23: =IFERROR((SUMIF('ITALIA'!E2:E67,$A23,'ITALIA'!P2:P67)+SUMIF('GERMANIA'!E2:E44,$A23,'GERMANIA'!P2:P44)+SUMIF('FRANCIA'!E2:E36,$A23,'FRANCIA'!P2:P36)+SUMIF('PAESI BASSI'!E2:E21,$A23,'PAESI BASSI'!P2:P21)+SUMIF('SVIZZERA'!E2:E24,$A23,'SVIZZERA'!P2:P24)+SUMIF('USA'!E2:E167,$A23,'USA'!P2:P167))/(COUNTIFS('ITALIA'!E2:E67,$A23,'ITALIA'!P2:P67,"<>")+COUNTIFS('GERMANIA'!E2:E44,$A23,'GERMANIA'!P2:P44,"<>")+COUNTIFS('FRANCIA'!E2:E36,$A23,'FRANCIA'!P2:P36,"<>")+COUNTIFS('PAESI BASSI'!E2:E21,$A23,'PAESI BASSI'!P2:P21,"<>")+COUNTIFS('SVIZZERA'!E2:E24,$A23,'SVIZZERA'!P2:P24,"<>")+COUNTIFS('USA'!E2:E167,$A23,'USA'!P2:P167,"<>")),"")
A24: Salute | B24: =COUNTIF('ITALIA'!E2:E67,$A24) | C24: =COUNTIF('GERMANIA'!E2:E44,$A24) | D24: =COUNTIF('FRANCIA'!E2:E36,$A24) | E24: =COUNTIF('PAESI BASSI'!E2:E21,$A24) | F24: =COUNTIF('SVIZZERA'!E2:E24,$A24) | G24: =COUNTIF('USA'!E2:E167,$A24) | H24: =SUM(B24:G24) | I24: =COUNTIFS('ITALIA'!E2:E67,$A24,'ITALIA'!AG2:AG67,"PASSA")+COUNTIFS('ITALIA'!E2:E67,$A24,'ITALIA'!AG2:AG67,"PASSA FORTE")+COUNTIFS('GERMANIA'!E2:E44,$A24,'GERMANIA'!AG2:AG44,"PASSA")+COUNTIFS('GERMANIA'!E2:E44,$A24,'GERMANIA'!AG2:AG44,"PASSA FORTE")+COUNTIFS('FRANCIA'!E2:E36,$A24,'FRANCIA'!AG2:AG36,"PASSA")+COUNTIFS('FRANCIA'!E2:E36,$A24,'FRANCIA'!AG2:AG36,"PASSA FORTE")+COUNTIFS('PAESI BASSI'!E2:E21,$A24,'PAESI BASSI'!AG2:AG21,"PASSA")+COUNTIFS('PAESI BASSI'!E2:E21,$A24,'PAESI BASSI'!AG2:AG21,"PASSA FORTE")+COUNTIFS('SVIZZERA'!E2:E24,$A24,'SVIZZERA'!AG2:AG24,"PASSA")+COUNTIFS('SVIZZERA'!E2:E24,$A24,'SVIZZERA'!AG2:AG24,"PASSA FORTE")+COUNTIFS('USA'!E2:E167,$A24,'USA'!AG2:AG167,"PASSA")+COUNTIFS('USA'!E2:E167,$A24,'USA'!AG2:AG167,"PASSA FORTE") | J24: =IFERROR((SUMIF('ITALIA'!E2:E67,$A24,'ITALIA'!P2:P67)+SUMIF('GERMANIA'!E2:E44,$A24,'GERMANIA'!P2:P44)+SUMIF('FRANCIA'!E2:E36,$A24,'FRANCIA'!P2:P36)+SUMIF('PAESI BASSI'!E2:E21,$A24,'PAESI BASSI'!P2:P21)+SUMIF('SVIZZERA'!E2:E24,$A24,'SVIZZERA'!P2:P24)+SUMIF('USA'!E2:E167,$A24,'USA'!P2:P167))/(COUNTIFS('ITALIA'!E2:E67,$A24,'ITALIA'!P2:P67,"<>")+COUNTIFS('GERMANIA'!E2:E44,$A24,'GERMANIA'!P2:P44,"<>")+COUNTIFS('FRANCIA'!E2:E36,$A24,'FRANCIA'!P2:P36,"<>")+COUNTIFS('PAESI BASSI'!E2:E21,$A24,'PAESI BASSI'!P2:P21,"<>")+COUNTIFS('SVIZZERA'!E2:E24,$A24,'SVIZZERA'!P2:P24,"<>")+COUNTIFS('USA'!E2:E167,$A24,'USA'!P2:P167,"<>")),"")
A25: Finanziario | B25: =COUNTIF('ITALIA'!E2:E67,$A25) | C25: =COUNTIF('GERMANIA'!E2:E44,$A25) | D25: =COUNTIF('FRANCIA'!E2:E36,$A25) | E25: =COUNTIF('PAESI BASSI'!E2:E21,$A25) | F25: =COUNTIF('SVIZZERA'!E2:E24,$A25) | G25: =COUNTIF('USA'!E2:E167,$A25) | H25: =SUM(B25:G25) | I25: =COUNTIFS('ITALIA'!E2:E67,$A25,'ITALIA'!AG2:AG67,"PASSA")+COUNTIFS('ITALIA'!E2:E67,$A25,'ITALIA'!AG2:AG67,"PASSA FORTE")+COUNTIFS('GERMANIA'!E2:E44,$A25,'GERMANIA'!AG2:AG44,"PASSA")+COUNTIFS('GERMANIA'!E2:E44,$A25,'GERMANIA'!AG2:AG44,"PASSA FORTE")+COUNTIFS('FRANCIA'!E2:E36,$A25,'FRANCIA'!AG2:AG36,"PASSA")+COUNTIFS('FRANCIA'!E2:E36,$A25,'FRANCIA'!AG2:AG36,"PASSA FORTE")+COUNTIFS('PAESI BASSI'!E2:E21,$A25,'PAESI BASSI'!AG2:AG21,"PASSA")+COUNTIFS('PAESI BASSI'!E2:E21,$A25,'PAESI BASSI'!AG2:AG21,"PASSA FORTE")+COUNTIFS('SVIZZERA'!E2:E24,$A25,'SVIZZERA'!AG2:AG24,"PASSA")+COUNTIFS('SVIZZERA'!E2:E24,$A25,'SVIZZERA'!AG2:AG24,"PASSA FORTE")+COUNTIFS('USA'!E2:E167,$A25,'USA'!AG2:AG167,"PASSA")+COUNTIFS('USA'!E2:E167,$A25,'USA'!AG2:AG167,"PASSA FORTE") | J25: =IFERROR((SUMIF('ITALIA'!E2:E67,$A25,'ITALIA'!P2:P67)+SUMIF('GERMANIA'!E2:E44,$A25,'GERMANIA'!P2:P44)+SUMIF('FRANCIA'!E2:E36,$A25,'FRANCIA'!P2:P36)+SUMIF('PAESI BASSI'!E2:E21,$A25,'PAESI BASSI'!P2:P21)+SUMIF('SVIZZERA'!E2:E24,$A25,'SVIZZERA'!P2:P24)+SUMIF('USA'!E2:E167,$A25,'USA'!P2:P167))/(COUNTIFS('ITALIA'!E2:E67,$A25,'ITALIA'!P2:P67,"<>")+COUNTIFS('GERMANIA'!E2:E44,$A25,'GERMANIA'!P2:P44,"<>")+COUNTIFS('FRANCIA'!E2:E36,$A25,'FRANCIA'!P2:P36,"<>")+COUNTIFS('PAESI BASSI'!E2:E21,$A25,'PAESI BASSI'!P2:P21,"<>")+COUNTIFS('SVIZZERA'!E2:E24,$A25,'SVIZZERA'!P2:P24,"<>")+COUNTIFS('USA'!E2:E167,$A25,'USA'!P2:P167,"<>")),"")
A26: Industriale | B26: =COUNTIF('ITALIA'!E2:E67,$A26) | C26: =COUNTIF('GERMANIA'!E2:E44,$A26) | D26: =COUNTIF('FRANCIA'!E2:E36,$A26) | E26: =COUNTIF('PAESI BASSI'!E2:E21,$A26) | F26: =COUNTIF('SVIZZERA'!E2:E24,$A26) | G26: =COUNTIF('USA'!E2:E167,$A26) | H26: =SUM(B26:G26) | I26: =COUNTIFS('ITALIA'!E2:E67,$A26,'ITALIA'!AG2:AG67,"PASSA")+COUNTIFS('ITALIA'!E2:E67,$A26,'ITALIA'!AG2:AG67,"PASSA FORTE")+COUNTIFS('GERMANIA'!E2:E44,$A26,'GERMANIA'!AG2:AG44,"PASSA")+COUNTIFS('GERMANIA'!E2:E44,$A26,'GERMANIA'!AG2:AG44,"PASSA FORTE")+COUNTIFS('FRANCIA'!E2:E36,$A26,'FRANCIA'!AG2:AG36,"PASSA")+COUNTIFS('FRANCIA'!E2:E36,$A26,'FRANCIA'!AG2:AG36,"PASSA FORTE")+COUNTIFS('PAESI BASSI'!E2:E21,$A26,'PAESI BASSI'!AG2:AG21,"PASSA")+COUNTIFS('PAESI BASSI'!E2:E21,$A26,'PAESI BASSI'!AG2:AG21,"PASSA FORTE")+COUNTIFS('SVIZZERA'!E2:E24,$A26,'SVIZZERA'!AG2:AG24,"PASSA")+COUNTIFS('SVIZZERA'!E2:E24,$A26,'SVIZZERA'!AG2:AG24,"PASSA FORTE")+COUNTIFS('USA'!E2:E167,$A26,'USA'!AG2:AG167,"PASSA")+COUNTIFS('USA'!E2:E167,$A26,'USA'!AG2:AG167,"PASSA FORTE") | J26: =IFERROR((SUMIF('ITALIA'!E2:E67,$A26,'ITALIA'!P2:P67)+SUMIF('GERMANIA'!E2:E44,$A26,'GERMANIA'!P2:P44)+SUMIF('FRANCIA'!E2:E36,$A26,'FRANCIA'!P2:P36)+SUMIF('PAESI BASSI'!E2:E21,$A26,'PAESI BASSI'!P2:P21)+SUMIF('SVIZZERA'!E2:E24,$A26,'SVIZZERA'!P2:P24)+SUMIF('USA'!E2:E167,$A26,'USA'!P2:P167))/(COUNTIFS('ITALIA'!E2:E67,$A26,'ITALIA'!P2:P67,"<>")+COUNTIFS('GERMANIA'!E2:E44,$A26,'GERMANIA'!P2:P44,"<>")+COUNTIFS('FRANCIA'!E2:E36,$A26,'FRANCIA'!P2:P36,"<>")+COUNTIFS('PAESI BASSI'!E2:E21,$A26,'PAESI BASSI'!P2:P21,"<>")+COUNTIFS('SVIZZERA'!E2:E24,$A26,'SVIZZERA'!P2:P24,"<>")+COUNTIFS('USA'!E2:E167,$A26,'USA'!P2:P167,"<>")),"")
A27: Consumi | B27: =COUNTIF('ITALIA'!E2:E67,$A27) | C27: =COUNTIF('GERMANIA'!E2:E44,$A27) | D27: =COUNTIF('FRANCIA'!E2:E36,$A27) | E27: =COUNTIF('PAESI BASSI'!E2:E21,$A27) | F27: =COUNTIF('SVIZZERA'!E2:E24,$A27) | G27: =COUNTIF('USA'!E2:E167,$A27) | H27: =SUM(B27:G27) | I27: =COUNTIFS('ITALIA'!E2:E67,$A27,'ITALIA'!AG2:AG67,"PASSA")+COUNTIFS('ITALIA'!E2:E67,$A27,'ITALIA'!AG2:AG67,"PASSA FORTE")+COUNTIFS('GERMANIA'!E2:E44,$A27,'GERMANIA'!AG2:AG44,"PASSA")+COUNTIFS('GERMANIA'!E2:E44,$A27,'GERMANIA'!AG2:AG44,"PASSA FORTE")+COUNTIFS('FRANCIA'!E2:E36,$A27,'FRANCIA'!AG2:AG36,"PASSA")+COUNTIFS('FRANCIA'!E2:E36,$A27,'FRANCIA'!AG2:AG36,"PASSA FORTE")+COUNTIFS('PAESI BASSI'!E2:E21,$A27,'PAESI BASSI'!AG2:AG21,"PASSA")+COUNTIFS('PAESI BASSI'!E2:E21,$A27,'PAESI BASSI'!AG2:AG21,"PASSA FORTE")+COUNTIFS('SVIZZERA'!E2:E24,$A27,'SVIZZERA'!AG2:AG24,"PASSA")+COUNTIFS('SVIZZERA'!E2:E24,$A27,'SVIZZERA'!AG2:AG24,"PASSA FORTE")+COUNTIFS('USA'!E2:E167,$A27,'USA'!AG2:AG167,"PASSA")+COUNTIFS('USA'!E2:E167,$A27,'USA'!AG2:AG167,"PASSA FORTE") | J27: =IFERROR((SUMIF('ITALIA'!E2:E67,$A27,'ITALIA'!P2:P67)+SUMIF('GERMANIA'!E2:E44,$A27,'GERMANIA'!P2:P44)+SUMIF('FRANCIA'!E2:E36,$A27,'FRANCIA'!P2:P36)+SUMIF('PAESI BASSI'!E2:E21,$A27,'PAESI BASSI'!P2:P21)+SUMIF('SVIZZERA'!E2:E24,$A27,'SVIZZERA'!P2:P24)+SUMIF('USA'!E2:E167,$A27,'USA'!P2:P167))/(COUNTIFS('ITALIA'!E2:E67,$A27,'ITALIA'!P2:P67,"<>")+COUNTIFS('GERMANIA'!E2:E44,$A27,'GERMANIA'!P2:P44,"<>")+COUNTIFS('FRANCIA'!E2:E36,$A27,'FRANCIA'!P2:P36,"<>")+COUNTIFS('PAESI BASSI'!E2:E21,$A27,'PAESI BASSI'!P2:P21,"<>")+COUNTIFS('SVIZZERA'!E2:E24,$A27,'SVIZZERA'!P2:P24,"<>")+COUNTIFS('USA'!E2:E167,$A27,'USA'!P2:P167,"<>")),"")
A28: Energia | B28: =COUNTIF('ITALIA'!E2:E67,$A28) | C28: =COUNTIF('GERMANIA'!E2:E44,$A28) | D28: =COUNTIF('FRANCIA'!E2:E36,$A28) | E28: =COUNTIF('PAESI BASSI'!E2:E21,$A28) | F28: =COUNTIF('SVIZZERA'!E2:E24,$A28) | G28: =COUNTIF('USA'!E2:E167,$A28) | H28: =SUM(B28:G28) | I28: =COUNTIFS('ITALIA'!E2:E67,$A28,'ITALIA'!AG2:AG67,"PASSA")+COUNTIFS('ITALIA'!E2:E67,$A28,'ITALIA'!AG2:AG67,"PASSA FORTE")+COUNTIFS('GERMANIA'!E2:E44,$A28,'GERMANIA'!AG2:AG44,"PASSA")+COUNTIFS('GERMANIA'!E2:E44,$A28,'GERMANIA'!AG2:AG44,"PASSA FORTE")+COUNTIFS('FRANCIA'!E2:E36,$A28,'FRANCIA'!AG2:AG36,"PASSA")+COUNTIFS('FRANCIA'!E2:E36,$A28,'FRANCIA'!AG2:AG36,"PASSA FORTE")+COUNTIFS('PAESI BASSI'!E2:E21,$A28,'PAESI BASSI'!AG2:AG21,"PASSA")+COUNTIFS('PAESI BASSI'!E2:E21,$A28,'PAESI BASSI'!AG2:AG21,"PASSA FORTE")+COUNTIFS('SVIZZERA'!E2:E24,$A28,'SVIZZERA'!AG2:AG24,"PASSA")+COUNTIFS('SVIZZERA'!E2:E24,$A28,'SVIZZERA'!AG2:AG24,"PASSA FORTE")+COUNTIFS('USA'!E2:E167,$A28,'USA'!AG2:AG167,"PASSA")+COUNTIFS('USA'!E2:E167,$A28,'USA'!AG2:AG167,"PASSA FORTE") | J28: =IFERROR((SUMIF('ITALIA'!E2:E67,$A28,'ITALIA'!P2:P67)+SUMIF('GERMANIA'!E2:E44,$A28,'GERMANIA'!P2:P44)+SUMIF('FRANCIA'!E2:E36,$A28,'FRANCIA'!P2:P36)+SUMIF('PAESI BASSI'!E2:E21,$A28,'PAESI BASSI'!P2:P21)+SUMIF('SVIZZERA'!E2:E24,$A28,'SVIZZERA'!P2:P24)+SUMIF('USA'!E2:E167,$A28,'USA'!P2:P167))/(COUNTIFS('ITALIA'!E2:E67,$A28,'ITALIA'!P2:P67,"<>")+COUNTIFS('GERMANIA'!E2:E44,$A28,'GERMANIA'!P2:P44,"<>")+COUNTIFS('FRANCIA'!E2:E36,$A28,'FRANCIA'!P2:P36,"<>")+COUNTIFS('PAESI BASSI'!E2:E21,$A28,'PAESI BASSI'!P2:P21,"<>")+COUNTIFS('SVIZZERA'!E2:E24,$A28,'SVIZZERA'!P2:P24,"<>")+COUNTIFS('USA'!E2:E167,$A28,'USA'!P2:P167,"<>")),"")
A29: Utility | B29: =COUNTIF('ITALIA'!E2:E67,$A29) | C29: =COUNTIF('GERMANIA'!E2:E44,$A29) | D29: =COUNTIF('FRANCIA'!E2:E36,$A29) | E29: =COUNTIF('PAESI BASSI'!E2:E21,$A29) | F29: =COUNTIF('SVIZZERA'!E2:E24,$A29) | G29: =COUNTIF('USA'!E2:E167,$A29) | H29: =SUM(B29:G29) | I29: =COUNTIFS('ITALIA'!E2:E67,$A29,'ITALIA'!AG2:AG67,"PASSA")+COUNTIFS('ITALIA'!E2:E67,$A29,'ITALIA'!AG2:AG67,"PASSA FORTE")+COUNTIFS('GERMANIA'!E2:E44,$A29,'GERMANIA'!AG2:AG44,"PASSA")+COUNTIFS('GERMANIA'!E2:E44,$A29,'GERMANIA'!AG2:AG44,"PASSA FORTE")+COUNTIFS('FRANCIA'!E2:E36,$A29,'FRANCIA'!AG2:AG36,"PASSA")+COUNTIFS('FRANCIA'!E2:E36,$A29,'FRANCIA'!AG2:AG36,"PASSA FORTE")+COUNTIFS('PAESI BASSI'!E2:E21,$A29,'PAESI BASSI'!AG2:AG21,"PASSA")+COUNTIFS('PAESI BASSI'!E2:E21,$A29,'PAESI BASSI'!AG2:AG21,"PASSA FORTE")+COUNTIFS('SVIZZERA'!E2:E24,$A29,'SVIZZERA'!AG2:AG24,"PASSA")+COUNTIFS('SVIZZERA'!E2:E24,$A29,'SVIZZERA'!AG2:AG24,"PASSA FORTE")+COUNTIFS('USA'!E2:E167,$A29,'USA'!AG2:AG167,"PASSA")+COUNTIFS('USA'!E2:E167,$A29,'USA'!AG2:AG167,"PASSA FORTE") | J29: =IFERROR((SUMIF('ITALIA'!E2:E67,$A29,'ITALIA'!P2:P67)+SUMIF('GERMANIA'!E2:E44,$A29,'GERMANIA'!P2:P44)+SUMIF('FRANCIA'!E2:E36,$A29,'FRANCIA'!P2:P36)+SUMIF('PAESI BASSI'!E2:E21,$A29,'PAESI BASSI'!P2:P21)+SUMIF('SVIZZERA'!E2:E24,$A29,'SVIZZERA'!P2:P24)+SUMIF('USA'!E2:E167,$A29,'USA'!P2:P167))/(COUNTIFS('ITALIA'!E2:E67,$A29,'ITALIA'!P2:P67,"<>")+COUNTIFS('GERMANIA'!E2:E44,$A29,'GERMANIA'!P2:P44,"<>")+COUNTIFS('FRANCIA'!E2:E36,$A29,'FRANCIA'!P2:P36,"<>")+COUNTIFS('PAESI BASSI'!E2:E21,$A29,'PAESI BASSI'!P2:P21,"<>")+COUNTIFS('SVIZZERA'!E2:E24,$A29,'SVIZZERA'!P2:P24,"<>")+COUNTIFS('USA'!E2:E167,$A29,'USA'!P2:P167,"<>")),"")
A30: Materiali | B30: =COUNTIF('ITALIA'!E2:E67,$A30) | C30: =COUNTIF('GERMANIA'!E2:E44,$A30) | D30: =COUNTIF('FRANCIA'!E2:E36,$A30) | E30: =COUNTIF('PAESI BASSI'!E2:E21,$A30) | F30: =COUNTIF('SVIZZERA'!E2:E24,$A30) | G30: =COUNTIF('USA'!E2:E167,$A30) | H30: =SUM(B30:G30) | I30: =COUNTIFS('ITALIA'!E2:E67,$A30,'ITALIA'!AG2:AG67,"PASSA")+COUNTIFS('ITALIA'!E2:E67,$A30,'ITALIA'!AG2:AG67,"PASSA FORTE")+COUNTIFS('GERMANIA'!E2:E44,$A30,'GERMANIA'!AG2:AG44,"PASSA")+COUNTIFS('GERMANIA'!E2:E44,$A30,'GERMANIA'!AG2:AG44,"PASSA FORTE")+COUNTIFS('FRANCIA'!E2:E36,$A30,'FRANCIA'!AG2:AG36,"PASSA")+COUNTIFS('FRANCIA'!E2:E36,$A30,'FRANCIA'!AG2:AG36,"PASSA FORTE")+COUNTIFS('PAESI BASSI'!E2:E21,$A30,'PAESI BASSI'!AG2:AG21,"PASSA")+COUNTIFS('PAESI BASSI'!E2:E21,$A30,'PAESI BASSI'!AG2:AG21,"PASSA FORTE")+COUNTIFS('SVIZZERA'!E2:E24,$A30,'SVIZZERA'!AG2:AG24,"PASSA")+COUNTIFS('SVIZZERA'!E2:E24,$A30,'SVIZZERA'!AG2:AG24,"PASSA FORTE")+COUNTIFS('USA'!E2:E167,$A30,'USA'!AG2:AG167,"PASSA")+COUNTIFS('USA'!E2:E167,$A30,'USA'!AG2:AG167,"PASSA FORTE") | J30: =IFERROR((SUMIF('ITALIA'!E2:E67,$A30,'ITALIA'!P2:P67)+SUMIF('GERMANIA'!E2:E44,$A30,'GERMANIA'!P2:P44)+SUMIF('FRANCIA'!E2:E36,$A30,'FRANCIA'!P2:P36)+SUMIF('PAESI BASSI'!E2:E21,$A30,'PAESI BASSI'!P2:P21)+SUMIF('SVIZZERA'!E2:E24,$A30,'SVIZZERA'!P2:P24)+SUMIF('USA'!E2:E167,$A30,'USA'!P2:P167))/(COUNTIFS('ITALIA'!E2:E67,$A30,'ITALIA'!P2:P67,"<>")+COUNTIFS('GERMANIA'!E2:E44,$A30,'GERMANIA'!P2:P44,"<>")+COUNTIFS('FRANCIA'!E2:E36,$A30,'FRANCIA'!P2:P36,"<>")+COUNTIFS('PAESI BASSI'!E2:E21,$A30,'PAESI BASSI'!P2:P21,"<>")+COUNTIFS('SVIZZERA'!E2:E24,$A30,'SVIZZERA'!P2:P24,"<>")+COUNTIFS('USA'!E2:E167,$A30,'USA'!P2:P167,"<>")),"")
A31: Immobiliare | B31: =COUNTIF('ITALIA'!E2:E67,$A31) | C31: =COUNTIF('GERMANIA'!E2:E44,$A31) | D31: =COUNTIF('FRANCIA'!E2:E36,$A31) | E31: =COUNTIF('PAESI BASSI'!E2:E21,$A31) | F31: =COUNTIF('SVIZZERA'!E2:E24,$A31) | G31: =COUNTIF('USA'!E2:E167,$A31) | H31: =SUM(B31:G31) | I31: =COUNTIFS('ITALIA'!E2:E67,$A31,'ITALIA'!AG2:AG67,"PASSA")+COUNTIFS('ITALIA'!E2:E67,$A31,'ITALIA'!AG2:AG67,"PASSA FORTE")+COUNTIFS('GERMANIA'!E2:E44,$A31,'GERMANIA'!AG2:AG44,"PASSA")+COUNTIFS('GERMANIA'!E2:E44,$A31,'GERMANIA'!AG2:AG44,"PASSA FORTE")+COUNTIFS('FRANCIA'!E2:E36,$A31,'FRANCIA'!AG2:AG36,"PASSA")+COUNTIFS('FRANCIA'!E2:E36,$A31,'FRANCIA'!AG2:AG36,"PASSA FORTE")+COUNTIFS('PAESI BASSI'!E2:E21,$A31,'PAESI BASSI'!AG2:AG21,"PASSA")+COUNTIFS('PAESI BASSI'!E2:E21,$A31,'PAESI BASSI'!AG2:AG21,"PASSA FORTE")+COUNTIFS('SVIZZERA'!E2:E24,$A31,'SVIZZERA'!AG2:AG24,"PASSA")+COUNTIFS('SVIZZERA'!E2:E24,$A31,'SVIZZERA'!AG2:AG24,"PASSA FORTE")+COUNTIFS('USA'!E2:E167,$A31,'USA'!AG2:AG167,"PASSA")+COUNTIFS('USA'!E2:E167,$A31,'USA'!AG2:AG167,"PASSA FORTE") | J31: =IFERROR((SUMIF('ITALIA'!E2:E67,$A31,'ITALIA'!P2:P67)+SUMIF('GERMANIA'!E2:E44,$A31,'GERMANIA'!P2:P44)+SUMIF('FRANCIA'!E2:E36,$A31,'FRANCIA'!P2:P36)+SUMIF('PAESI BASSI'!E2:E21,$A31,'PAESI BASSI'!P2:P21)+SUMIF('SVIZZERA'!E2:E24,$A31,'SVIZZERA'!P2:P24)+SUMIF('USA'!E2:E167,$A31,'USA'!P2:P167))/(COUNTIFS('ITALIA'!E2:E67,$A31,'ITALIA'!P2:P67,"<>")+COUNTIFS('GERMANIA'!E2:E44,$A31,'GERMANIA'!P2:P44,"<>")+COUNTIFS('FRANCIA'!E2:E36,$A31,'FRANCIA'!P2:P36,"<>")+COUNTIFS('PAESI BASSI'!E2:E21,$A31,'PAESI BASSI'!P2:P21,"<>")+COUNTIFS('SVIZZERA'!E2:E24,$A31,'SVIZZERA'!P2:P24,"<>")+COUNTIFS('USA'!E2:E167,$A31,'USA'!P2:P167,"<>")),"")
A32: Veicolo | B32: =COUNTIF('ITALIA'!E2:E67,$A32) | C32: =COUNTIF('GERMANIA'!E2:E44,$A32) | D32: =COUNTIF('FRANCIA'!E2:E36,$A32) | E32: =COUNTIF('PAESI BASSI'!E2:E21,$A32) | F32: =COUNTIF('SVIZZERA'!E2:E24,$A32) | G32: =COUNTIF('USA'!E2:E167,$A32) | H32: =SUM(B32:G32) | I32: =COUNTIFS('ITALIA'!E2:E67,$A32,'ITALIA'!AG2:AG67,"PASSA")+COUNTIFS('ITALIA'!E2:E67,$A32,'ITALIA'!AG2:AG67,"PASSA FORTE")+COUNTIFS('GERMANIA'!E2:E44,$A32,'GERMANIA'!AG2:AG44,"PASSA")+COUNTIFS('GERMANIA'!E2:E44,$A32,'GERMANIA'!AG2:AG44,"PASSA FORTE")+COUNTIFS('FRANCIA'!E2:E36,$A32,'FRANCIA'!AG2:AG36,"PASSA")+COUNTIFS('FRANCIA'!E2:E36,$A32,'FRANCIA'!AG2:AG36,"PASSA FORTE")+COUNTIFS('PAESI BASSI'!E2:E21,$A32,'PAESI BASSI'!AG2:AG21,"PASSA")+COUNTIFS('PAESI BASSI'!E2:E21,$A32,'PAESI BASSI'!AG2:AG21,"PASSA FORTE")+COUNTIFS('SVIZZERA'!E2:E24,$A32,'SVIZZERA'!AG2:AG24,"PASSA")+COUNTIFS('SVIZZERA'!E2:E24,$A32,'SVIZZERA'!AG2:AG24,"PASSA FORTE")+COUNTIFS('USA'!E2:E167,$A32,'USA'!AG2:AG167,"PASSA")+COUNTIFS('USA'!E2:E167,$A32,'USA'!AG2:AG167,"PASSA FORTE") | J32: =IFERROR((SUMIF('ITALIA'!E2:E67,$A32,'ITALIA'!P2:P67)+SUMIF('GERMANIA'!E2:E44,$A32,'GERMANIA'!P2:P44)+SUMIF('FRANCIA'!E2:E36,$A32,'FRANCIA'!P2:P36)+SUMIF('PAESI BASSI'!E2:E21,$A32,'PAESI BASSI'!P2:P21)+SUMIF('SVIZZERA'!E2:E24,$A32,'SVIZZERA'!P2:P24)+SUMIF('USA'!E2:E167,$A32,'USA'!P2:P167))/(COUNTIFS('ITALIA'!E2:E67,$A32,'ITALIA'!P2:P67,"<>")+COUNTIFS('GERMANIA'!E2:E44,$A32,'GERMANIA'!P2:P44,"<>")+COUNTIFS('FRANCIA'!E2:E36,$A32,'FRANCIA'!P2:P36,"<>")+COUNTIFS('PAESI BASSI'!E2:E21,$A32,'PAESI BASSI'!P2:P21,"<>")+COUNTIFS('SVIZZERA'!E2:E24,$A32,'SVIZZERA'!P2:P24,"<>")+COUNTIFS('USA'!E2:E167,$A32,'USA'!P2:P167,"<>")),"")
A34: Il ROE contabile di banche e assicurazioni non e' confrontabile con quello degli industriali: leggi i settori separatamente.
A35: Le colonne PREZZO € e CAP. MLN € sono convertite al cambio del giorno della rilevazione: usa quelle per confrontare le dimensioni fra mercati diversi.
A36: PUNTEGGIO: redditivita' 40 + costanza 20 + prezzo 30 + crescita 10, meno 8 se l'ultimo esercizio e' molto sotto la media dei cinque anni. POS. e' la classifica dentro il foglio.

Sheet ITALIA
A1: POS. | B1: TITOLO | C1: TICKER | D1: SETTORE | E1: CLASSE | F1: PREZZO | G1: VAL. | H1: PREZZO € | I1: CAP. MLN € | J1: CAP. MLN locale | K1: EPS TTM | L1: EPS ATTESO | M1: P/E | N1: P/B | O1: ROE IMPL. | P1: ROE 1a | Q1: ROE 5a | R1: VARIAB. ROE | S1: ANNI | T1: 2026 | U1: 2025 | V1: 2024 | W1: 2023 | X1: 2022 | Y1: DIVID. | Z1: RENDIM. | AA1: DEBITO/MP | AB1: CRESC. RICAVI | AC1: MARGINE | AD1: PUNTEGGIO | AE1: ESITO ROE | AF1: ESITO P/E | AG1: GIUDIZIO | AH1: RILEVATO | AI1: FONTE | AJ1: NOTE
A2: =IF(AD2="","",RANK(AD2,AD$2:AD$67)) | B2: Azimut Holding | C2: AZM.MI | D2: Risparmio gestito | E2: Finanziario | F2: 36.26 | G2: EUR | H2: 36.26 | I2: 5065.8 | J2: 5065.8 | K2: 3.72 | L2: 3.59593 | M2: =IF(OR(F2="",K2="",K2<=0),"",F2/K2) | N2: 2.6043236 | O2: =IF(OR(N2="",M2="",M2<=0),"",N2/M2) | P2: 0.29348 | Q2: 0.28096481 | R2: 0.01535347 | S2: 4 | U2: 0.25725356 | V2: 0.29958273 | W2: 0.28026383 | X2: 0.28675913 | Y2: 2 | Z2: =IF(OR(Y2="",F2="",F2=0),"",Y2/F2) | AA2: 4.261 | AB2: 0.17 | AC2: 0.37491421 | AD2: =IF(OR(Q2="",M2="",M2<=0),"",ROUND(40*MAX(0,MIN(N(Q2)/0.3,1))+IF(OR(R2="",N(Q2)<=0),10,20*MAX(0,1-MIN(R2/Q2,1)))+30*MAX(0,MIN((PARAMETRI!$B$5-M2)/MAX(PARAMETRI!$B$5-10,1),1))+IF(AB2="",3,10*MAX(0,MIN(AB2/0.15,1)))+IF(AND(P2<>"",N(P2)<N(Q2)*0.6),-8,0),1)) | AE2: =IF(AND(P2="",Q2=""),"DATI MANCANTI",IF(AND(N(P2)>=PARAMETRI!$B$4,N(Q2)>=PARAMETRI!$B$4),"OK","NO")) | AF2: =IF(M2="","N/D",IF(M2<PARAMETRI!$B$6,"OTTIMO",IF(M2<PARAMETRI!$B$5,"OK","NO"))) | AG2: =IF(OR(AE2="DATI MANCANTI",AF2="N/D"),"DA COMPLETARE",IF(AND(AE2="OK",AF2="OTTIMO"),"PASSA FORTE",IF(AND(AE2="OK",AF2="OK"),"PASSA","SCARTA"))) | AH2: 2026-10-12 | AI2: yahoo
A3: =IF(AD3="","",RANK(AD3,AD$2:AD$67)) | B3: Banca Generali | C3: BGN.MI | D3: Risparmio gestito | E3: Finanziario | F3: 62.55 | G3: EUR | H3: 62.55 | I3: 7135.9 | J3: 7135.9 | K3: 4.6 | L3: 3.84504 | M3: =IF(OR(F3="",K3="",K3<=0),"",F3/K3) | N3: 5.0766983 | O3: =IF(OR(N3="",M3="",M3<=0),"",N3/M3) | P3: 0.36488 | Q3: 0.26188408 | R3: 0.037246672 | S3: 4 | U3: 0.28382224 | V3: 0.29537517 | W3: 0.26888345 | X3: 0.19945547 | Y3: 2.85 | Z3: =IF(OR(Y3="",F3="",F3=0),"",Y3/F3) | AB3: 0.464 | AC3: 0.4480064 | AD3: =IF(OR(Q3="",M3="",M3<=0),"",ROUND(40*MAX(0,MIN(N(Q3)/0.3,1))+IF(OR(R3="",N(Q3)<=0),10,20*MAX(0,1-MIN(R3/Q3,1)))+30*MAX(0,MIN((PARAMETRI!$B$5-M3)/MAX(PARAMETRI!$B$5-10,1),1))+IF(AB3="",3,10*MAX(0,MIN(AB3/0.15,1)))+IF(AND(P3<>"",N(P3)<N(Q3)*0.6),-8,0),1)) | AE3: =IF(AND(P3="",Q3=""),"DATI MANCANTI",IF(AND(N(P3)>=PARAMETRI!$B$4,N(Q3)>=PARAMETRI!$B$4),"OK","NO")) | AF3: =IF(M3="","N/D",IF(M3<PARAMETRI!$B$6,"OTTIMO",IF(M3<PARAMETRI!$B$5,"OK","NO"))) | AG3: =IF(OR(AE3="DATI MANCANTI",AF3="N/D"),"DA COMPLETARE",IF(AND(AE3="OK",AF3="OTTIMO"),"PASSA FORTE",IF(AND(AE3="OK",AF3="OK"),"PASSA","SCARTA"))) | AH3: 2026-10-12 | AI3: yahoo
A4: =IF(AD4="","",RANK(AD4,AD$2:AD$67)) | B4: Banca Mediolanum | C4: BMED.MI | D4: Banca | E4: Finanziario | F4: 23 | G4: EUR | H4: 23 | I4: 17004.2 | J4: 17004.2 | K4: 1.77 | L4: 1.57559 | M4: =IF(OR(F4="",K4="",K4<=0),"",F4/K4) | N4: 3.7210805 | O4: =IF(OR(N4="",M4="",M4<=0),"",N4/M4) | P4: 0.30062 | Q4: 0.24084367 | R4: 0.042850695 | S4: 4 | U4: 0.27543582 | V4: 0.27811895 | W4: 0.23789634 | X4: 0.17192358 | Y4: 1.3 | Z4: =IF(OR(Y4="",F4="",F4=0),"",Y4/F4) | AB4: 0.29 | AC4: 0.53929675 | AD4: =IF(OR(Q4="",M4="",M4<=0),"",ROUND(40*MAX(0,MIN(N(Q4)/0.3,1))+IF(OR(R4="",N(Q4)<=0),10,20*MAX(0,1-MIN(R4/Q4,1)))+30*MAX(0,MIN((PARAMETRI!$B$5-M4)/MAX(PARAMETRI!$B$5-10,1),1))+IF(AB4="",3,10*MAX(0,MIN(AB4/0.15,1)))+IF(AND(P4<>"",N(P4)<N(Q4)*0.6),-8,0),1)) | AE4: =IF(AND(P4="",Q4=""),"DATI MANCANTI",IF(AND(N(P4)>=PARAMETRI!$B$4,N(Q4)>=PARAMETRI!$B$4),"OK","NO")) | AF4: =IF(M4="","N/D",IF(M4<PARAMETRI!$B$6,"OTTIMO",IF(M4<PARAMETRI!$B$5,"OK","NO"))) | AG4: =IF(OR(AE4="DATI MANCANTI",AF4="N/D"),"DA COMPLETARE",IF(AND(AE4="OK",AF4="OTTIMO"),"PASSA FORTE",IF(AND(AE4="OK",AF4="OK"),"PASSA","SCARTA"))) | AH4: 2026-10-12 | AI4: yahoo
A5: =IF(AD5="","",RANK(AD5,AD$2:AD$67)) | B5: Mondadori Editore | C5: MN.MI | D5: Editoria / Media | E5: Industriale | F5: 2.04 | G5: EUR | H5: 2.04 | I5: 532.1 | J5: 532.1 | K5: 0.2 | L5: 0.23706 | M5: =IF(OR(F5="",K5="",K5<=0),"",F5/K5) | N5: 1.8279569 | O5: =IF(OR(N5="",M5="",M5<=0),"",N5/M5) | P5: 0.18361 | Q5: 0.19271184 | R5: 0.019468584 | S5: 4 | U5: 0.16310796 | V5: 0.19050135 | W5: 0.21664243 | X5: 0.20059562 | Y5: 0.15 | Z5: =IF(OR(Y5="",F5="",F5=0),"",Y5/F5) | AA5: 129.372 | AB5: 0.089 | AC5: 0.055788974 | AD5: =IF(OR(Q5="",M5="",M5<=0),"",ROUND(40*MAX(0,MIN(N(Q5)/0.3,1))+IF(OR(R5="",N(Q5)<=0),10,20*MAX(0,1-MIN(R5/Q5,1)))+30*MAX(0,MIN((PARAMETRI!$B$5-M5)/MAX(PARAMETRI!$B$5-10,1),1))+IF(AB5="",3,10*MAX(0,MIN(AB5/0.15,1)))+IF(AND(P5<>"",N(P5)<N(Q5)*0.6),-8,0),1)) | AE5: =IF(AND(P5="",Q5=""),"DATI MANCANTI",IF(AND(N(P5)>=PARAMETRI!$B$4,N(Q5)>=PARAMETRI!$B$4),"OK","NO")) | AF5: =IF(M5="","N/D",IF(M5<PARAMETRI!$B$6,"OTTIMO",IF(M5<PARAMETRI!$B$5,"OK","NO"))) | AG5: =IF(OR(AE5="DATI MANCANTI",AF5="N/D"),"DA COMPLETARE",IF(AND(AE5="OK",AF5="OTTIMO"),"PASSA FORTE",IF(AND(AE5="OK",AF5="OK"),"PASSA","SCARTA"))) | AH5: 2026-10-12 | AI5: yahoo
A6: =IF(AD6="","",RANK(AD6,AD$2:AD$67)) | B6: Italgas | C6: IG.MI | D6: Utility / Reti | E6: Utility | F6: 8.252 | G6: EUR | H6: 8.252 | I6: 8388.3 | J6: 8388.3 | K6: 0.68 | L6: 0.79922 | M6: =IF(OR(F6="",K6="",K6<=0),"",F6/K6) | N6: 2.2248583 | O6: =IF(OR(N6="",M6="",M6<=0),"",N6/M6) | P6: 0.19063 | Q6: 0.18921117 | R6: 0.007636667 | S6: 4 | U6: 0.1760501 | V6: 0.19482106 | W6: 0.19278689 | X6: 0.19318662 | Y6: 0.43 | Z6: =IF(OR(Y6="",F6="",F6=0),"",Y6/F6) | AA6: 294.061 | AB6: 0.306 | AC6: 0.20630459 | AD6: =IF(OR(Q6="",M6="",M6<=0),"",ROUND(40*MAX(0,MIN(N(Q6)/0.3,1))+IF(OR(R6="",N(Q6)<=0),10,20*MAX(0,1-MIN(R6/Q6,1)))+30*MAX(0,MIN((PARAMETRI!$B$5-M6)/MAX(PARAMETRI!$B$5-10,1),1))+IF(AB6="",3,10*MAX(0,MIN(AB6/0.15,1)))+IF(AND(P6<>"",N(P6)<N(Q6)*0.6),-8,0),1)) | AE6: =IF(AND(P6="",Q6=""),"DATI MANCANTI",IF(AND(N(P6)>=PARAMETRI!$B$4,N(Q6)>=PARAMETRI!$B$4),"OK","NO")) | AF6: =IF(M6="","N/D",IF(M6<PARAMETRI!$B$6,"OTTIMO",IF(M6<PARAMETRI!$B$5,"OK","NO"))) | AG6: =IF(OR(AE6="DATI MANCANTI",AF6="N/D"),"DA COMPLETARE",IF(AND(AE6="OK",AF6="OTTIMO"),"PASSA FORTE",IF(AND(AE6="OK",AF6="OK"),"PASSA","SCARTA"))) | AH6: 2026-10-12 | AI6: yahoo
A7: =IF(AD7="","",RANK(AD7,AD$2:AD$67)) | B7: A2A | C7: A2A.MI | D7: Utility | E7: Utility | F7: 2.32 | G7: EUR | H7: 2.32 | I7: 7263.9 | J7: 7263.9 | K7: 0.22 | L7: 0.21117 | M7: =IF(OR(F7="",K7="",K7<=0),"",F7/K7) | N7: 1.3959086 | O7: =IF(OR(N7="",M7="",M7<=0),"",N7/M7) | P7: 0.11337 | Q7: 0.13528765 | R7: 0.02216392 | S7: 4 | U7: 0.12675342 | V7: 0.15612577 | W7: 0.15542453 | X7: 0.10284688 | Y7: 0.1 | Z7: =IF(OR(Y7="",F7="",F7=0),"",Y7/F7) | AA7: 113.764 | AB7: 0.314 | AC7: 0.050003639 | AD7: =IF(OR(Q7="",M7="",M7<=0),"",ROUND(40*MAX(0,MIN(N(Q7)/0.3,1))+IF(OR(R7="",N(Q7)<=0),10,20*MAX(0,1-MIN(R7/Q7,1)))+30*MAX(0,MIN((PARAMETRI!$B$5-M7)/MAX(PARAMETRI!$B$5-10,1),1))+IF(AB7="",3,10*MAX(0,MIN(AB7/0.15,1)))+IF(AND(P7<>"",N(P7)<N(Q7)*0.6),-8,0),1)) | AE7: =IF(AND(P7="",Q7=""),"DATI MANCANTI",IF(AND(N(P7)>=PARAMETRI!$B$4,N(Q7)>=PARAMETRI!$B$4),"OK","NO")) | AF7: =IF(M7="","N/D",IF(M7<PARAMETRI!$B$6,"OTTIMO",IF(M7<PARAMETRI!$B$5,"OK","NO"))) | AG7: =IF(OR(AE7="DATI MANCANTI",AF7="N/D"),"DA COMPLETARE",IF(AND(AE7="OK",AF7="OTTIMO"),"PASSA FORTE",IF(AND(AE7="OK",AF7="OK"),"PASSA","SCARTA"))) | AH7: 2026-10-12 | AI7: yahoo
A8: =IF(AD8="","",RANK(AD8,AD$2:AD$67)) | B8: Maire | C8: MAIRE.MI | D8: Impiantistica | E8: Industriale | F8: 12.72 | G8: EUR | H8: 12.72 | I8: 4155.3 | J8: 4155.3 | K8: 0.83 | L8: 1.02473 | M8: =IF(OR(F8="",K8="",K8<=0),"",F8/K8) | N8: 7.1702366 | O8: =IF(OR(N8="",M8="",M8<=0),"",N8/M8) | P8: 0.48770002 | Q8: 0.27984755 | R8: 0.072988074 | S8: 4 | U8: 0.36511535 | V8: 0.33347432 | W8: 0.23793896 | X8: 0.18286158 | Y8: 0.59 | Z8: =IF(OR(Y8="",F8="",F8=0),"",Y8/F8) | AA8: 235.473 | AB8: 0.095 | AC8: 0.03901697 | AD8: =IF(OR(Q8="",M8="",M8<=0),"",ROUND(40*MAX(0,MIN(N(Q8)/0.3,1))+IF(OR(R8="",N(Q8)<=0),10,20*MAX(0,1-MIN(R8/Q8,1)))+30*MAX(0,MIN((PARAMETRI!$B$5-M8)/MAX(PARAMETRI!$B$5-10,1),1))+IF(AB8="",3,10*MAX(0,MIN(AB8/0.15,1)))+IF(AND(P8<>"",N(P8)<N(Q8)*0.6),-8,0),1)) | AE8: =IF(AND(P8="",Q8=""),"DATI MANCANTI",IF(AND(N(P8)>=PARAMETRI!$B$4,N(Q8)>=PARAMETRI!$B$4),"OK","NO")) | AF8: =IF(M8="","N/D",IF(M8<PARAMETRI!$B$6,"OTTIMO",IF(M8<PARAMETRI!$B$5,"OK","NO"))) | AG8: =IF(OR(AE8="DATI MANCANTI",AF8="N/D"),"DA COMPLETARE",IF(AND(AE8="OK",AF8="OTTIMO"),"PASSA FORTE",IF(AND(AE8="OK",AF8="OK"),"PASSA","SCARTA"))) | AH8: 2026-10-12 | AI8: yahoo
A9: =IF(AD9="","",RANK(AD9,AD$2:AD$67)) | B9: Unipol | C9: UNI.MI | D9: Assicurazione | E9: Finanziario | F9: 24.92 | G9: EUR | H9: 24.92 | I9: 18380.4 | J9: 18380.4 | K9: 2.39 | L9: 2.26656 | M9: =IF(OR(F9="",K9="",K9<=0),"",F9/K9) | N9: 1.7794917 | O9: =IF(OR(N9="",M9="",M9<=0),"",N9/M9) | P9: 0.16938 | Q9: 0.11813762 | R9: 0.02618848 | S9: 4 | U9: 0.14262342 | V9: 0.11522369 | W9: 0.13819505 | X9: 0.076508307 | Y9: 1.12 | Z9: =IF(OR(Y9="",F9="",F9=0),"",Y9/F9) | AA9: 40.819 | AB9: 0.232 | AC9: 0.12542843 | AD9: =IF(OR(Q9="",M9="",M9<=0),"",ROUND(40*MAX(0,MIN(N(Q9)/0.3,1))+IF(OR(R9="",N(Q9)<=0),10,20*MAX(0,1-MIN(R9/Q9,1)))+30*MAX(0,MIN((PARAMETRI!$B$5-M9)/MAX(PARAMETRI!$B$5-10,1),1))+IF(AB9="",3,10*MAX(0,MIN(AB9/0.15,1)))+IF(AND(P9<>"",N(P9)<N(Q9)*0.6),-8,0),1)) | AE9: =IF(AND(P9="",Q9=""),"DATI MANCANTI",IF(AND(N(P9)>=PARAMETRI!$B$4,N(Q9)>=PARAMETRI!$B$4),"OK","NO")) | AF9: =IF(M9="","N/D",IF(M9<PARAMETRI!$B$6,"OTTIMO",IF(M9<PARAMETRI!$B$5,"OK","NO"))) | AG9: =IF(OR(AE9="DATI MANCANTI",AF9="N/D"),"DA COMPLETARE",IF(AND(AE9="OK",AF9="OTTIMO"),"PASSA FORTE",IF(AND(AE9="OK",AF9="OK"),"PASSA","SCARTA"))) | AH9: 2026-10-12 | AI9: yahoo
A10: =IF(AD10="","",RANK(AD10,AD$2:AD$67)) | B10: BPER Banca | C10: BPE.MI | D10: Banca | E10: Finanziario | F10: 13.584 | G10: EUR | H10: 13.584 | I10: 28419.5 | J10: 28419.5 | K10: 1.12 | L10: 1.30349 | M10: =IF(OR(F10="",K10="",K10<=0),"",F10/K10) | N10: 1.5729505 | O10: =IF(OR(N10="",M10="",M10<=0),"",N10/M10) | P10: 0.15279001 | Q10: 0.1445087 | R10: 0.029165584 | S10: 4 | U10: 0.10977616 | V10: 0.12353932 | W10: 0.16223274 | X10: 0.18248658 | Y10: 0.66 | Z10: =IF(OR(Y10="",F10="",F10=0),"",Y10/F10) | AB10: 0.54 | AC10: 0.31426131 | AD10: =IF(OR(Q10="",M10="",M10<=0),"",ROUND(40*MAX(0,MIN(N(Q10)/0.3,1))+IF(OR(R10="",N(Q10)<=0),10,20*MAX(0,1-MIN(R10/Q10,1)))+30*MAX(0,MIN((PARAMETRI!$B$5-M10)/MAX(PARAMETRI!$B$5-10,1),1))+IF(AB10="",3,10*MAX(0,MIN(AB10/0.15,1)))+IF(AND(P10<>"",N(P10)<N(Q10)*0.6),-8,0),1)) | AE10: =IF(AND(P10="",Q10=""),"DATI MANCANTI",IF(AND(N(P10)>=PARAMETRI!$B$4,N(Q10)>=PARAMETRI!$B$4),"OK","NO")) | AF10: =IF(M10="","N/D",IF(M10<PARAMETRI!$B$6,"OTTIMO",IF(M10<PARAMETRI!$B$5,"OK","NO"))) | AG10: =IF(OR(AE10="DATI MANCANTI",AF10="N/D"),"DA COMPLETARE",IF(AND(AE10="OK",AF10="OTTIMO"),"PASSA FORTE",IF(AND(AE10="OK",AF10="OK"),"PASSA","SCARTA"))) | AH10: 2026-10-12 | AI10: yahoo
A11: =IF(AD11="","",RANK(AD11,AD$2:AD$67)) | B11: Hera | C11: HER.MI | D11: Utility | E11: Utility | F11: 3.48 | G11: EUR | H11: 3.48 | I11: 5144.7 | J11: 5144.7 | K11: 0.32 | L11: 0.33202 | M11: =IF(OR(F11="",K11="",K11<=0),"",F11/K11) | N11: 1.2599565 | O11: =IF(OR(N11="",M11="",M11<=0),"",N11/M11) | P11: 0.12108 | Q11: 0.11290166 | R11: 0.023079781 | S11: 4 | U11: 0.11375998 | V11: 0.13437135 | W11: 0.12838113 | X11: 0.075094162 | Y11: 0.16 | Z11: =IF(OR(Y11="",F11="",F11=0),"",Y11/F11) | AA11: 133.318 | AB11: 0.217 | AC11: 0.036293651 | AD11: =IF(OR(Q11="",M11="",M11<=0),"",ROUND(40*MAX(0,MIN(N(Q11)/0.3,1))+IF(OR(R11="",N(Q11)<=0),10,20*MAX(0,1-MIN(R11/Q11,1)))+30*MAX(0,MIN((PARAMETRI!$B$5-M11)/MAX(PARAMETRI!$B$5-10,1),1))+IF(AB11="",3,10*MAX(0,MIN(AB11/0.15,1)))+IF(AND(P11<>"",N(P11)<N(Q11)*0.6),-8,0),1)) | AE11: =IF(AND(P11="",Q11=""),"DATI MANCANTI",IF(AND(N(P11)>=PARAMETRI!$B$4,N(Q11)>=PARAMETRI!$B$4),"OK","NO")) | AF11: =IF(M11="","N/D",IF(M11<PARAMETRI!$B$6,"OTTIMO",IF(M11<PARAMETRI!$B$5,"OK","NO"))) | AG11: =IF(OR(AE11="DATI MANCANTI",AF11="N/D"),"DA COMPLETARE",IF(AND(AE11="OK",AF11="OTTIMO"),"PASSA FORTE",IF(AND(AE11="OK",AF11="OK"),"PASSA","SCARTA"))) | AH11: 2026-10-12 | AI11: yahoo
A12: =IF(AD12="","",RANK(AD12,AD$2:AD$67)) | B12: Credito Emiliano | C12: CE.MI | D12: Banca | E12: Finanziario | F12: 20.04 | G12: EUR | H12: 20.04 | I12: 6815.3 | J12: 6815.3 | K12: 1.66 | L12: 1.70798 | M12: =IF(OR(F12="",K12="",K12<=0),"",F12/K12) | N12: 1.4429724 | O12: =IF(OR(N12="",M12="",M12<=0),"",N12/M12) | P12: 0.12286 | Q12: 0.13000628 | R12: 0.019597562 | S12: 4 | U12: 0.133281 | V12: 0.14444985 | W12: 0.14522979 | X12: 0.097064484 | Y12: 0.75 | Z12: =IF(OR(Y12="",F12="",F12=0),"",Y12/F12) | AB12: 0.165 | AC12: 0.27106269 | AD12: =IF(OR(Q12="",M12="",M12<=0),"",ROUND(40*MAX(0,MIN(N(Q12)/0.3,1))+IF(OR(R12="",N(Q12)<=0),10,20*MAX(0,1-MIN(R12/Q12,1)))+30*MAX(0,MIN((PARAMETRI!$B$5-M12)/MAX(PARAMETRI!$B$5-10,1),1))+IF(AB12="",3,10*MAX(0,MIN(AB12/0.15,1)))+IF(AND(P12<>"",N(P12)<N(Q12)*0.6),-8,0),1)) | AE12: =IF(AND(P12="",Q12=""),"DATI MANCANTI",IF(AND(N(P12)>=PARAMETRI!$B$4,N(Q12)>=PARAMETRI!$B$4),"OK","NO")) | AF12: =IF(M12="","N/D",IF(M12<PARAMETRI!$B$6,"OTTIMO",IF(M12<PARAMETRI!$B$5,"OK","NO"))) | AG12: =IF(OR(AE12="DATI MANCANTI",AF12="N/D"),"DA COMPLETARE",IF(AND(AE12="OK",AF12="OTTIMO"),"PASSA FORTE",IF(AND(AE12="OK",AF12="OK"),"PASSA","SCARTA"))) | AH12: 2026-10-12 | AI12: yahoo
A13: =IF(AD13="","",RANK(AD13,AD$2:AD$67)) | B13: RCS MediaGroup | C13: RCS.MI | D13: Editoria / Media | E13: Industriale | F13: 0.831 | G13: EUR | H13: 0.831 | I13: 429.9 | J13: 429.9 | K13: 0.11 | L13: 0.11 | M13: =IF(OR(F13="",K13="",K13<=0),"",F13/K13) | N13: 0.9347581 | O13: =IF(OR(N13="",M13="",M13<=0),"",N13/M13) | P13: 0.11979999 | Q13: 0.13134594 | R13: 0.0083535013 | S13: 4 | U13: 0.11907866 | V13: 0.140494 | W13: 0.1373825 | X13: 0.12842861 | Y13: 0.07 | Z13: =IF(OR(Y13="",F13="",F13=0),"",Y13/F13) | AA13: 29.396 | AB13: 0.004 | AC13: 0.068427066 | AD13: =IF(OR(Q13="",M13="",M13<=0),"",ROUND(40*MAX(0,MIN(N(Q13)/0.3,1))+IF(OR(R13="",N(Q13)<=0),10,20*MAX(0,1-MIN(R13/Q13,1)))+30*MAX(0,MIN((PARAMETRI!$B$5-M13)/MAX(PARAMETRI!$B$5-10,1),1))+IF(AB13="",3,10*MAX(0,MIN(AB13/0.15,1)))+IF(AND(P13<>"",N(P13)<N(Q13)*0.6),-8,0),1)) | AE13: =IF(AND(P13="",Q13=""),"DATI MANCANTI",IF(AND(N(P13)>=PARAMETRI!$B$4,N(Q13)>=PARAMETRI!$B$4),"OK","NO")) | AF13: =IF(M13="","N/D",IF(M13<PARAMETRI!$B$6,"OTTIMO",IF(M13<PARAMETRI!$B$5,"OK","NO"))) | AG13: =IF(OR(AE13="DATI MANCANTI",AF13="N/D"),"DA COMPLETARE",IF(AND(AE13="OK",AF13="OTTIMO"),"PASSA FORTE",IF(AND(AE13="OK",AF13="OK"),"PASSA","SCARTA"))) | AH13: 2026-10-12 | AI13: yahoo
A14: =IF(AD14="","",RANK(AD14,AD$2:AD$67)) | B14: Poste Italiane | C14: PST.MI | D14: Servizi finanziari | E14: Finanziario | F14: 24.35 | G14: EUR | H14: 24.35 | I14: 38895.6 | J14: 38895.6 | K14: 1.85 | L14: 1.98583 | M14: =IF(OR(F14="",K14="",K14<=0),"",F14/K14) | N14: 2.4553797 | O14: =IF(OR(N14="",M14="",M14<=0),"",N14/M14) | P14: 0.18174 | Q14: 0.17994135 | R14: 0.015492288 | S14: 4 | U14: 0.15998266 | V14: 0.17214884 | W14: 0.18620422 | X14: 0.20142967 | Y14: 1.25 | Z14: =IF(OR(Y14="",F14="",F14=0),"",Y14/F14) | AA14: 631.496 | AB14: 0.034 | AC14: 0.10319474 | AD14: =IF(OR(Q14="",M14="",M14<=0),"",ROUND(40*MAX(0,MIN(N(Q14)/0.3,1))+IF(OR(R14="",N(Q14)<=0),10,20*MAX(0,1-MIN(R14/Q14,1)))+30*MAX(0,MIN((PARAMETRI!$B$5-M14)/MAX(PARAMETRI!$B$5-10,1),1))+IF(AB14="",3,10*MAX(0,MIN(AB14/0.15,1)))+IF(AND(P14<>"",N(P14)<N(Q14)*0.6),-8,0),1)) | AE14: =IF(AND(P14="",Q14=""),"DATI MANCANTI",IF(AND(N(P14)>=PARAMETRI!$B$4,N(Q14)>=PARAMETRI!$B$4),"OK","NO")) | AF14: =IF(M14="","N/D",IF(M14<PARAMETRI!$B$6,"OTTIMO",IF(M14<PARAMETRI!$B$5,"OK","NO"))) | AG14: =IF(OR(AE14="DATI MANCANTI",AF14="N/D"),"DA COMPLETARE",IF(AND(AE14="OK",AF14="OTTIMO"),"PASSA FORTE",IF(AND(AE14="OK",AF14="OK"),"PASSA","SCARTA"))) | AH14: 2026-10-12 | AI14: yahoo
A15: =IF(AD15="","",RANK(AD15,AD$2:AD$67)) | B15: FinecoBank | C15: FBK.MI | D15: Banca | E15: Finanziario | F15: 21.3 | G15: EUR | H15: 21.3 | I15: 13031.7 | J15: 13031.7 | K15: 1.1 | L15: 1.28801 | M15: =IF(OR(F15="",K15="",K15<=0),"",F15/K15) | N15: 5.4378347 | O15: =IF(OR(N15="",M15="",M15<=0),"",N15/M15) | P15: 0.28855 | Q15: 0.25706242 | R15: 0.020975024 | S15: 4 | U15: 0.25341124 | V15: 0.27300118 | W15: 0.27753573 | X15: 0.22430155 | Y15: 0.79 | Z15: =IF(OR(Y15="",F15="",F15=0),"",Y15/F15) | AB15: 0.18 | AC15: 0.43118985 | AD15: =IF(OR(Q15="",M15="",M15<=0),"",ROUND(40*MAX(0,MIN(N(Q15)/0.3,1))+IF(OR(R15="",N(Q15)<=0),10,20*MAX(0,1-MIN(R15/Q15,1)))+30*MAX(0,MIN((PARAMETRI!$B$5-M15)/MAX(PARAMETRI!$B$5-10,1),1))+IF(AB15="",3,10*MAX(0,MIN(AB15/0.15,1)))+IF(AND(P15<>"",N(P15)<N(Q15)*0.6),-8,0),1)) | AE15: =IF(AND(P15="",Q15=""),"DATI MANCANTI",IF(AND(N(P15)>=PARAMETRI!$B$4,N(Q15)>=PARAMETRI!$B$4),"OK","NO")) | AF15: =IF(M15="","N/D",IF(M15<PARAMETRI!$B$6,"OTTIMO",IF(M15<PARAMETRI!$B$5,"OK","NO"))) | AG15: =IF(OR(AE15="DATI MANCANTI",AF15="N/D"),"DA COMPLETARE",IF(AND(AE15="OK",AF15="OTTIMO"),"PASSA FORTE",IF(AND(AE15="OK",AF15="OK"),"PASSA","SCARTA"))) | AH15: 2026-10-12 | AI15: yahoo
A16: =IF(AD16="","",RANK(AD16,AD$2:AD$67)) | B16: Ferrari | C16: RACE.MI | D16: Lusso / Auto | E16: Consumi | F16: 351 | G16: EUR | H16: 351 | I16: 61565.4 | J16: 61565.4 | K16: 9.23 | L16: 11.05319 | M16: =IF(OR(F16="",K16="",K16<=0),"",F16/K16) | N16: 16.878246 | O16: =IF(OR(N16="",M16="",M16<=0),"",N16/M16) | P16: 0.45439997 | Q16: 0.4020306 | R16: 0.026010469 | S16: 4 | U16: 0.40874398 | V16: 0.43064523 | W16: 0.40904731 | X16: 0.35968586 | Y16: 3.62 | Z16: =IF(OR(Y16="",F16="",F16=0),"",Y16/F16) | AA16: 86.386 | AB16: 0.084 | AC16: 0.22896293 | AD16: =IF(OR(Q16="",M16="",M16<=0),"",ROUND(40*MAX(0,MIN(N(Q16)/0.3,1))+IF(OR(R16="",N(Q16)<=0),10,20*MAX(0,1-MIN(R16/Q16,1)))+30*MAX(0,MIN((PARAMETRI!$B$5-M16)/MAX(PARAMETRI!$B$5-10,1),1))+IF(AB16="",3,10*MAX(0,MIN(AB16/0.15,1)))+IF(AND(P16<>"",N(P16)<N(Q16)*0.6),-8,0),1)) | AE16: =IF(AND(P16="",Q16=""),"DATI MANCANTI",IF(AND(N(P16)>=PARAMETRI!$B$4,N(Q16)>=PARAMETRI!$B$4),"OK","NO")) | AF16: =IF(M16="","N/D",IF(M16<PARAMETRI!$B$6,"OTTIMO",IF(M16<PARAMETRI!$B$5,"OK","NO"))) | AG16: =IF(OR(AE16="DATI MANCANTI",AF16="N/D"),"DA COMPLETARE",IF(AND(AE16="OK",AF16="OTTIMO"),"PASSA FORTE",IF(AND(AE16="OK",AF16="OK"),"PASSA","SCARTA"))) | AH16: 2026-10-12 | AI16: yahoo
A17: =IF(AD17="","",RANK(AD17,AD$2:AD$67)) | B17: Acea | C17: ACE.MI | D17: Utility | E17: Utility | F17: 20.24 | G17: EUR | H17: 20.24 | I17: 4302 | J17: 4302 | K17: 1.7 | L17: 1.58975 | M17: =IF(OR(F17="",K17="",K17<=0),"",F17/K17) | N17: 1.4436519 | O17: =IF(OR(N17="",M17="",M17<=0),"",N17/M17) | P17: 0.12430999 | Q17: 0.1377274 | R17: 0.020635625 | S17: 4 | U17: 0.17281687 | V17: 0.13237768 | W17: 0.123632 | X17: 0.12208306 | Y17: 0.95 | Z17: =IF(OR(Y17="",F17="",F17=0),"",Y17/F17) | AA17: 169.549 | AB17: 0.063 | AC17: 0.13134802 | AD17: =IF(OR(Q17="",M17="",M17<=0),"",ROUND(40*MAX(0,MIN(N(Q17)/0.3,1))+IF(OR(R17="",N(Q17)<=0),10,20*MAX(0,1-MIN(R17/Q17,1)))+30*MAX(0,MIN((PARAMETRI!$B$5-M17)/MAX(PARAMETRI!$B$5-10,1),1))+IF(AB17="",3,10*MAX(0,MIN(AB17/0.15,1)))+IF(AND(P17<>"",N(P17)<N(Q17)*0.6),-8,0),1)) | AE17: =IF(AND(P17="",Q17=""),"DATI MANCANTI",IF(AND(N(P17)>=PARAMETRI!$B$4,N(Q17)>=PARAMETRI!$B$4),"OK","NO")) | AF17: =IF(M17="","N/D",IF(M17<PARAMETRI!$B$6,"OTTIMO",IF(M17<PARAMETRI!$B$5,"OK","NO"))) | AG17: =IF(OR(AE17="DATI MANCANTI",AF17="N/D"),"DA COMPLETARE",IF(AND(AE17="OK",AF17="OTTIMO"),"PASSA FORTE",IF(AND(AE17="OK",AF17="OK"),"PASSA","SCARTA"))) | AH17: 2026-10-12 | AI17: yahoo
A18: =IF(AD18="","",RANK(AD18,AD$2:AD$67)) | B18: Buzzi | C18: BZU.MI | D18: Materiali / Cemento | E18: Materiali | F18: 37.14 | G18: EUR | H18: 37.14 | I18: 6552 | J18: 6552 | K18: 4.76 | L18: 4.83455 | M18: =IF(OR(F18="",K18="",K18<=0),"",F18/K18) | N18: 0.9003636 | O18: =IF(OR(N18="",M18="",M18<=0),"",N18/M18) | P18: 0.12303001 | Q18: 0.13450632 | R18: 0.028097184 | S18: 4 | U18: 0.13000006 | V18: 0.14271871 | W18: 0.17178884 | X18: 0.093517651 | Y18: 0.7 | Z18: =IF(OR(Y18="",F18="",F18=0),"",Y18/F18) | AA18: 6.827 | AB18: 0.001 | AC18: 0.19009803 | AD18: =IF(OR(Q18="",M18="",M18<=0),"",ROUND(40*MAX(0,MIN(N(Q18)/0.3,1))+IF(OR(R18="",N(Q18)<=0),10,20*MAX(0,1-MIN(R18/Q18,1)))+30*MAX(0,MIN((PARAMETRI!$B$5-M18)/MAX(PARAMETRI!$B$5-10,1),1))+IF(AB18="",3,10*MAX(0,MIN(AB18/0.15,1)))+IF(AND(P18<>"",N(P18)<N(Q18)*0.6),-8,0),1)) | AE18: =IF(AND(P18="",Q18=""),"DATI MANCANTI",IF(AND(N(P18)>=PARAMETRI!$B$4,N(Q18)>=PARAMETRI!$B$4),"OK","NO")) | AF18: =IF(M18="","N/D",IF(M18<PARAMETRI!$B$6,"OTTIMO",IF(M18<PARAMETRI!$B$5,"OK","NO"))) | AG18: =IF(OR(AE18="DATI MANCANTI",AF18="N/D"),"DA COMPLETARE",IF(AND(AE18="OK",AF18="OTTIMO"),"PASSA FORTE",IF(AND(AE18="OK",AF18="OK"),"PASSA","SCARTA"))) | AH18: 2026-10-12 | AI18: yahoo
A19: =IF(AD19="","",RANK(AD19,AD$2:AD$67)) | B19: UniCredit | C19: UCG.MI | D19: Banca | E19: Finanziario | F19: 76.25 | G19: EUR | H19: 76.25 | I19: 114981.4 | J19: 114981.4 | K19: 6.98 | L19: 8.41137 | M19: =IF(OR(F19="",K19="",K19<=0),"",F19/K19) | N19: 1.6223059 | O19: =IF(OR(N19="",M19="",M19<=0),"",N19/M19) | P19: 0.15779 | Q19: 0.14179344 | R19: 0.023444428 | S19: 4 | U19: 0.16119981 | V19: 0.15565093 | W19: 0.14836374 | X19: 0.1019593 | Y19: 3.15 | Z19: =IF(OR(Y19="",F19="",F19=0),"",Y19/F19) | AB19: -0.092 | AC19: 0.42849155 | AD19: =IF(OR(Q19="",M19="",M19<=0),"",ROUND(40*MAX(0,MIN(N(Q19)/0.3,1))+IF(OR(R19="",N(Q19)<=0),10,20*MAX(0,1-MIN(R19/Q19,1)))+30*MAX(0,MIN((PARAMETRI!$B$5-M19)/MAX(PARAMETRI!$B$5-10,1),1))+IF(AB19="",3,10*MAX(0,MIN(AB19/0.15,1)))+IF(AND(P19<>"",N(P19)<N(Q19)*0.6),-8,0),1)) | AE19: =IF(AND(P19="",Q19=""),"DATI MANCANTI",IF(AND(N(P19)>=PARAMETRI!$B$4,N(Q19)>=PARAMETRI!$B$4),"OK","NO")) | AF19: =IF(M19="","N/D",IF(M19<PARAMETRI!$B$6,"OTTIMO",IF(M19<PARAMETRI!$B$5,"OK","NO"))) | AG19: =IF(OR(AE19="DATI MANCANTI",AF19="N/D"),"DA COMPLETARE",IF(AND(AE19="OK",AF19="OTTIMO"),"PASSA FORTE",IF(AND(AE19="OK",AF19="OK"),"PASSA","SCARTA"))) | AH19: 2026-10-12 | AI19: yahoo
A20: =IF(AD20="","",RANK(AD20,AD$2:AD$67)) | B20: MFE-MediaForEurope A | C20: MFEA.MI | D20: Media / TV | E20: Industriale | F20: 2.086 | G20: EUR | H20: 2.086 | I20: 1462 | J20: 1462 | K20: 0.19 | L20: 0.48792 | M20: =IF(OR(F20="",K20="",K20<=0),"",F20/K20) | N20: 0.41895962 | O20: =IF(OR(N20="",M20="",M20<=0),"",N20/M20) | P20: 0.055760004 | Q20: 0.072151633 | R20: 0.014705008 | S20: 4 | U20: 0.086321229 | V20: 0.048070555 | W20: 0.072914851 | X20: 0.081299899 | Y20: 0.22 | Z20: =IF(OR(Y20="",F20="",F20=0),"",Y20/F20) | AA20: 88.622 | AB20: 0.945 | AC20: 0.04109692 | AD20: =IF(OR(Q20="",M20="",M20<=0),"",ROUND(40*MAX(0,MIN(N(Q20)/0.3,1))+IF(OR(R20="",N(Q20)<=0),10,20*MAX(0,1-MIN(R20/Q20,1)))+30*MAX(0,MIN((PARAMETRI!$B$5-M20)/MAX(PARAMETRI!$B$5-10,1),1))+IF(AB20="",3,10*MAX(0,MIN(AB20/0.15,1)))+IF(AND(P20<>"",N(P20)<N(Q20)*0.6),-8,0),1)) | AE20: =IF(AND(P20="",Q20=""),"DATI MANCANTI",IF(AND(N(P20)>=PARAMETRI!$B$4,N(Q20)>=PARAMETRI!$B$4),"OK","NO")) | AF20: =IF(M20="","N/D",IF(M20<PARAMETRI!$B$6,"OTTIMO",IF(M20<PARAMETRI!$B$5,"OK","NO"))) | AG20: =IF(OR(AE20="DATI MANCANTI",AF20="N/D"),"DA COMPLETARE",IF(AND(AE20="OK",AF20="OTTIMO"),"PASSA FORTE",IF(AND(AE20="OK",AF20="OK"),"PASSA","SCARTA"))) | AH20: 2026-10-12 | AI20: yahoo
A21: =IF(AD21="","",RANK(AD21,AD$2:AD$67)) | B21: Intesa Sanpaolo | C21: ISP.MI | D21: Banca | E21: Finanziario | F21: 6.184 | G21: EUR | H21: 6.184 | I21: 106934.3 | J21: 106934.3 | K21: 0.56 | L21: 0.65382 | M21: =IF(OR(F21="",K21="",K21<=0),"",F21/K21) | N21: 1.5815856 | O21: =IF(OR(N21="",M21="",M21<=0),"",N21/M21) | P21: 0.14261 | Q21: 0.11707234 | R21: 0.02736362 | S21: 4 | U21: 0.14290314 | V21: 0.13296305 | W21: 0.12075731 | X21: 0.071665876 | Y21: 0.38 | Z21: =IF(OR(Y21="",F21="",F21=0),"",Y21/F21) | AB21: 0.064 | AC21: 0.33856777 | AD21: =IF(OR(Q21="",M21="",M21<=0),"",ROUND(40*MAX(0,MIN(N(Q21)/0.3,1))+IF(OR(R21="",N(Q21)<=0),10,20*MAX(0,1-MIN(R21/Q21,1)))+30*MAX(0,MIN((PARAMETRI!$B$5-M21)/MAX(PARAMETRI!$B$5-10,1),1))+IF(AB21="",3,10*MAX(0,MIN(AB21/0.15,1)))+IF(AND(P21<>"",N(P21)<N(Q21)*0.6),-8,0),1)) | AE21: =IF(AND(P21="",Q21=""),"DATI MANCANTI",IF(AND(N(P21)>=PARAMETRI!$B$4,N(Q21)>=PARAMETRI!$B$4),"OK","NO")) | AF21: =IF(M21="","N/D",IF(M21<PARAMETRI!$B$6,"OTTIMO",IF(M21<PARAMETRI!$B$5,"OK","NO"))) | AG21: =IF(OR(AE21="DATI MANCANTI",AF21="N/D"),"DA COMPLETARE",IF(AND(AE21="OK",AF21="OTTIMO"),"PASSA FORTE",IF(AND(AE21="OK",AF21="OK"),"PASSA","SCARTA"))) | AH21: 2026-10-12 | AI21: yahoo
A22: =IF(AD22="","",RANK(AD22,AD$2:AD$67)) | B22: Iren | C22: IRE.MI | D22: Utility | E22: Utility | F22: 2.402 | G22: EUR | H22: 2.402 | I22: 3081.9 | J22: 3081.9 | K22: 0.23 | L22: 0.24707 | M22: =IF(OR(F22="",K22="",K22<=0),"",F22/K22) | N22: 1.0452567 | O22: =IF(OR(N22="",M22="",M22<=0),"",N22/M22) | P22: 0.08586001 | Q22: 0.088337892 | R22: 0.0041596522 | S22: 4 | U22: 0.086886862 | V22: 0.093347969 | W22: 0.090781581 | X22: 0.082335155 | Y22: 0.14 | Z22: =IF(OR(Y22="",F22="",F22=0),"",Y22/F22) | AA22: 129.504 | AB22: 0.028 | AC22: 0.046420933 | AD22: =IF(OR(Q22="",M22="",M22<=0),"",ROUND(40*MAX(0,MIN(N(Q22)/0.3,1))+IF(OR(R22="",N(Q22)<=0),10,20*MAX(0,1-MIN(R22/Q22,1)))+30*MAX(0,MIN((PARAMETRI!$B$5-M22)/MAX(PARAMETRI!$B$5-10,1),1))+IF(AB22="",3,10*MAX(0,MIN(AB22/0.15,1)))+IF(AND(P22<>"",N(P22)<N(Q22)*0.6),-8,0),1)) | AE22: =IF(AND(P22="",Q22=""),"DATI MANCANTI",IF(AND(N(P22)>=PARAMETRI!$B$4,N(Q22)>=PARAMETRI!$B$4),"OK","NO")) | AF22: =IF(M22="","N/D",IF(M22<PARAMETRI!$B$6,"OTTIMO",IF(M22<PARAMETRI!$B$5,"OK","NO"))) | AG22: =IF(OR(AE22="DATI MANCANTI",AF22="N/D"),"DA COMPLETARE",IF(AND(AE22="OK",AF22="OTTIMO"),"PASSA FORTE",IF(AND(AE22="OK",AF22="OK"),"PASSA","SCARTA"))) | AH22: 2026-10-12 | AI22: yahoo
A23: =IF(AD23="","",RANK(AD23,AD$2:AD$67)) | B23: Banca Ifis | C23: IF.MI | D23: Banca | E23: Finanziario | F23: 10.15 | G23: EUR | H23: 10.15 | I23: 620 | J23: 620 | K23: 4.22 | L23: 1.95776 | M23: =IF(OR(F23="",K23="",K23<=0),"",F23/K23) | N23: 0.30243436 | O23: =IF(OR(N23="",M23="",M23<=0),"",N23/M23) | P23: 0.12864 | Q23: 0.10808371 | R23: 0.027030354 | S23: 4 | U23: 0.15473378 | V23: 0.093273144 | W23: 0.095334271 | X23: 0.088993654 | Y23: 2.12 | Z23: =IF(OR(Y23="",F23="",F23=0),"",Y23/F23) | AB23: -0.253 | AC23: 0.34675755 | AD23: =IF(OR(Q23="",M23="",M23<=0),"",ROUND(40*MAX(0,MIN(N(Q23)/0.3,1))+IF(OR(R23="",N(Q23)<=0),10,20*MAX(0,1-MIN(R23/Q23,1)))+30*MAX(0,MIN((PARAMETRI!$B$5-M23)/MAX(PARAMETRI!$B$5-10,1),1))+IF(AB23="",3,10*MAX(0,MIN(AB23/0.15,1)))+IF(AND(P23<>"",N(P23)<N(Q23)*0.6),-8,0),1)) | AE23: =IF(AND(P23="",Q23=""),"DATI MANCANTI",IF(AND(N(P23)>=PARAMETRI!$B$4,N(Q23)>=PARAMETRI!$B$4),"OK","NO")) | AF23: =IF(M23="","N/D",IF(M23<PARAMETRI!$B$6,"OTTIMO",IF(M23<PARAMETRI!$B$5,"OK","NO"))) | AG23: =IF(OR(AE23="DATI MANCANTI",AF23="N/D"),"DA COMPLETARE",IF(AND(AE23="OK",AF23="OTTIMO"),"PASSA FORTE",IF(AND(AE23="OK",AF23="OK"),"PASSA","SCARTA"))) | AH23: 2026-10-12 | AI23: yahoo
A24: =IF(AD24="","",RANK(AD24,AD$2:AD$67)) | B24: Banca Monte dei Paschi | C24: BMPS.MI | D24: Banca | E24: Finanziario | F24: 11.15 | G24: EUR | H24: 11.15 | I24: 33878.4 | J24: 33878.4 | K24: 1.19 | L24: 0.89188 | M24: =IF(OR(F24="",K24="",K24<=0),"",F24/K24) | N24: 1.283084 | O24: =IF(OR(N24="",M24="",M24<=0),"",N24/M24) | P24: 0.15022 | Q24: 0.1118793 | R24: 0.086897105 | S24: 4 | U24: 0.097124119 | V24: 0.16746431 | W24: 0.20562105 | X24: -0.022692257 | Y24: 0.86 | Z24: =IF(OR(Y24="",F24="",F24=0),"",Y24/F24) | AB24: 0.995 | AC24: 0.58804123 | AD24: =IF(OR(Q24="",M24="",M24<=0),"",ROUND(40*MAX(0,MIN(N(Q24)/0.3,1))+IF(OR(R24="",N(Q24)<=0),10,20*MAX(0,1-MIN(R24/Q24,1)))+30*MAX(0,MIN((PARAMETRI!$B$5-M24)/MAX(PARAMETRI!$B$5-10,1),1))+IF(AB24="",3,10*MAX(0,MIN(AB24/0.15,1)))+IF(AND(P24<>"",N(P24)<N(Q24)*0.6),-8,0),1)) | AE24: =IF(AND(P24="",Q24=""),"DATI MANCANTI",IF(AND(N(P24)>=PARAMETRI!$B$4,N(Q24)>=PARAMETRI!$B$4),"OK","NO")) | AF24: =IF(M24="","N/D",IF(M24<PARAMETRI!$B$6,"OTTIMO",IF(M24<PARAMETRI!$B$5,"OK","NO"))) | AG24: =IF(OR(AE24="DATI MANCANTI",AF24="N/D"),"DA COMPLETARE",IF(AND(AE24="OK",AF24="OTTIMO"),"PASSA FORTE",IF(AND(AE24="OK",AF24="OK"),"PASSA","SCARTA"))) | AH24: 2026-10-12 | AI24: yahoo
A25: =IF(AD25="","",RANK(AD25,AD$2:AD$67)) | B25: Brunello Cucinelli | C25: BC.MI | D25: Lusso | E25: Consumi | F25: 81.2 | G25: EUR | H25: 81.2 | I25: 5521.6 | J25: 5521.6 | K25: 2.03 | L25: 2.62682 | M25: =IF(OR(F25="",K25="",K25<=0),"",F25/K25) | N25: 10.076942 | O25: =IF(OR(N25="",M25="",M25<=0),"",N25/M25) | P25: 0.26791 | Q25: 0.24032482 | R25: 0.01805966 | S25: 4 | U25: 0.24730596 | V25: 0.24386351 | W25: 0.25943715 | X25: 0.21069265 | Y25: 1.04 | Z25: =IF(OR(Y25="",F25="",F25=0),"",Y25/F25) | AA25: 217.133 | AB25: 0.095 | AC25: 0.097938772 | AD25: =IF(OR(Q25="",M25="",M25<=0),"",ROUND(40*MAX(0,MIN(N(Q25)/0.3,1))+IF(OR(R25="",N(Q25)<=0),10,20*MAX(0,1-MIN(R25/Q25,1)))+30*MAX(0,MIN((PARAMETRI!$B$5-M25)/MAX(PARAMETRI!$B$5-10,1),1))+IF(AB25="",3,10*MAX(0,MIN(AB25/0.15,1)))+IF(AND(P25<>"",N(P25)<N(Q25)*0.6),-8,0),1)) | AE25: =IF(AND(P25="",Q25=""),"DATI MANCANTI",IF(AND(N(P25)>=PARAMETRI!$B$4,N(Q25)>=PARAMETRI!$B$4),"OK","NO")) | AF25: =IF(M25="","N/D",IF(M25<PARAMETRI!$B$6,"OTTIMO",IF(M25<PARAMETRI!$B$5,"OK","NO"))) | AG25: =IF(OR(AE25="DATI MANCANTI",AF25="N/D"),"DA COMPLETARE",IF(AND(AE25="OK",AF25="OTTIMO"),"PASSA FORTE",IF(AND(AE25="OK",AF25="OK"),"PASSA","SCARTA"))) | AH25: 2026-10-12 | AI25: yahoo
A26: =IF(AD26="","",RANK(AD26,AD$2:AD$67)) | B26: Brembo | C26: BRE.MI | D26: Componentistica auto | E26: Industriale | F26: 9.94 | G26: EUR | H26: 9.94 | I26: 3162 | J26: 3162 | K26: 0.72 | L26: 0.84929 | M26: =IF(OR(F26="",K26="",K26<=0),"",F26/K26) | N26: 1.3496265 | O26: =IF(OR(N26="",M26="",M26<=0),"",N26/M26) | P26: 0.10133001 | Q26: 0.12656566 | R26: 0.025146184 | S26: 4 | U26: 0.091288645 | V26: 0.1144502 | W26: 0.14751898 | X26: 0.15300481 | Y26: 0.3 | Z26: =IF(OR(Y26="",F26="",F26=0),"",Y26/F26) | AA26: 58.738 | AB26: 0.061 | AC26: 0.061535021 | AD26: =IF(OR(Q26="",M26="",M26<=0),"",ROUND(40*MAX(0,MIN(N(Q26)/0.3,1))+IF(OR(R26="",N(Q26)<=0),10,20*MAX(0,1-MIN(R26/Q26,1)))+30*MAX(0,MIN((PARAMETRI!$B$5-M26)/MAX(PARAMETRI!$B$5-10,1),1))+IF(AB26="",3,10*MAX(0,MIN(AB26/0.15,1)))+IF(AND(P26<>"",N(P26)<N(Q26)*0.6),-8,0),1)) | AE26: =IF(AND(P26="",Q26=""),"DATI MANCANTI",IF(AND(N(P26)>=PARAMETRI!$B$4,N(Q26)>=PARAMETRI!$B$4),"OK","NO")) | AF26: =IF(M26="","N/D",IF(M26<PARAMETRI!$B$6,"OTTIMO",IF(M26<PARAMETRI!$B$5,"OK","NO"))) | AG26: =IF(OR(AE26="DATI MANCANTI",AF26="N/D"),"DA COMPLETARE",IF(AND(AE26="OK",AF26="OTTIMO"),"PASSA FORTE",IF(AND(AE26="OK",AF26="OK"),"PASSA","SCARTA"))) | AH26: 2026-10-12 | AI26: yahoo
A27: =IF(AD27="","",RANK(AD27,AD$2:AD$67)) | B27: Recordati | C27: REC.MI | D27: Farmaceutica | E27: Salute | F27: 52.95 | G27: EUR | H27: 52.95 | I27: 11013.6 | J27: 11013.6 | K27: 2.38 | L27: 3.7615 | M27: =IF(OR(F27="",K27="",K27<=0),"",F27/K27) | N27: 5.089878 | O27: =IF(OR(N27="",M27="",M27<=0),"",N27/M27) | P27: 0.24851999 | Q27: 0.22144951 | R27: 0.011819602 | S27: 4 | U27: 0.23108161 | V27: 0.22192349 | W27: 0.23079687 | X27: 0.20199606 | Y27: 1.42 | Z27: =IF(OR(Y27="",F27="",F27=0),"",Y27/F27) | AA27: 108.586 | AB27: 0.083 | AC27: 0.1898794 | AD27: =IF(OR(Q27="",M27="",M27<=0),"",ROUND(40*MAX(0,MIN(N(Q27)/0.3,1))+IF(OR(R27="",N(Q27)<=0),10,20*MAX(0,1-MIN(R27/Q27,1)))+30*MAX(0,MIN((PARAMETRI!$B$5-M27)/MAX(PARAMETRI!$B$5-10,1),1))+IF(AB27="",3,10*MAX(0,MIN(AB27/0.15,1)))+IF(AND(P27<>"",N(P27)<N(Q27)*0.6),-8,0),1)) | AE27: =IF(AND(P27="",Q27=""),"DATI MANCANTI",IF(AND(N(P27)>=PARAMETRI!$B$4,N(Q27)>=PARAMETRI!$B$4),"OK","NO")) | AF27: =IF(M27="","N/D",IF(M27<PARAMETRI!$B$6,"OTTIMO",IF(M27<PARAMETRI!$B$5,"OK","NO"))) | AG27: =IF(OR(AE27="DATI MANCANTI",AF27="N/D"),"DA COMPLETARE",IF(AND(AE27="OK",AF27="OTTIMO"),"PASSA FORTE",IF(AND(AE27="OK",AF27="OK"),"PASSA","SCARTA"))) | AH27: 2026-10-12 | AI27: yahoo
A28: =IF(AD28="","",RANK(AD28,AD$2:AD$67)) | B28: Assicurazioni Generali | C28: G.MI | D28: Assicurazione | E28: Finanziario | F28: 42.06 | G28: EUR | H28: 42.06 | I28: 63182.9 | J28: 63182.9 | K28: 2.95 | L28: 3.40268 | M28: =IF(OR(F28="",K28="",K28<=0),"",F28/K28) | N28: 1.9810654 | O28: =IF(OR(N28="",M28="",M28<=0),"",N28/M28) | P28: 0.1514 | Q28: 0.1164673 | R28: 0.019052157 | S28: 4 | U28: 0.13011477 | V28: 0.12254434 | W28: 0.12934516 | X28: 0.083864916 | Y28: 1.64 | Z28: =IF(OR(Y28="",F28="",F28=0),"",Y28/F28) | AA28: 118.93 | AB28: 0.054 | AC28: 0.061052435 | AD28: =IF(OR(Q28="",M28="",M28<=0),"",ROUND(40*MAX(0,MIN(N(Q28)/0.3,1))+IF(OR(R28="",N(Q28)<=0),10,20*MAX(0,1-MIN(R28/Q28,1)))+30*MAX(0,MIN((PARAMETRI!$B$5-M28)/MAX(PARAMETRI!$B$5-10,1),1))+IF(AB28="",3,10*MAX(0,MIN(AB28/0.15,1)))+IF(AND(P28<>"",N(P28)<N(Q28)*0.6),-8,0),1)) | AE28: =IF(AND(P28="",Q28=""),"DATI MANCANTI",IF(AND(N(P28)>=PARAMETRI!$B$4,N(Q28)>=PARAMETRI!$B$4),"OK","NO")) | AF28: =IF(M28="","N/D",IF(M28<PARAMETRI!$B$6,"OTTIMO",IF(M28<PARAMETRI!$B$5,"OK","NO"))) | AG28: =IF(OR(AE28="DATI MANCANTI",AF28="N/D"),"DA COMPLETARE",IF(AND(AE28="OK",AF28="OTTIMO"),"PASSA FORTE",IF(AND(AE28="OK",AF28="OK"),"PASSA","SCARTA"))) | AH28: 2026-10-12 | AI28: yahoo
A29: =IF(AD29="","",RANK(AD29,AD$2:AD$67)) | B29: Banca Profilo | C29: PRO.MI | D29: Banca | E29: Finanziario | F29: 1.482 | G29: EUR | H29: 1.482 | I29: 97.9 | J29: 97.9 | K29: 0.13 | L29: 0.158 | M29: =IF(OR(F29="",K29="",K29<=0),"",F29/K29) | N29: 0.60663116 | O29: =IF(OR(N29="",M29="",M29<=0),"",N29/M29) | P29: 0.05441 | Q29: 0.065030776 | R29: 0.006357037 | S29: 4 | U29: 0.060088544 | V29: 0.057656964 | W29: 0.073060489 | X29: 0.069317106 | Y29: 0.07 | Z29: =IF(OR(Y29="",F29="",F29=0),"",Y29/F29) | AB29: -0.28 | AC29: 0.1279504 | AD29: =IF(OR(Q29="",M29="",M29<=0),"",ROUND(40*MAX(0,MIN(N(Q29)/0.3,1))+IF(OR(R29="",N(Q29)<=0),10,20*MAX(0,1-MIN(R29/Q29,1)))+30*MAX(0,MIN((PARAMETRI!$B$5-M29)/MAX(PARAMETRI!$B$5-10,1),1))+IF(AB29="",3,10*MAX(0,MIN(AB29/0.15,1)))+IF(AND(P29<>"",N(P29)<N(Q29)*0.6),-8,0),1)) | AE29: =IF(AND(P29="",Q29=""),"DATI MANCANTI",IF(AND(N(P29)>=PARAMETRI!$B$4,N(Q29)>=PARAMETRI!$B$4),"OK","NO")) | AF29: =IF(M29="","N/D",IF(M29<PARAMETRI!$B$6,"OTTIMO",IF(M29<PARAMETRI!$B$5,"OK","NO"))) | AG29: =IF(OR(AE29="DATI MANCANTI",AF29="N/D"),"DA COMPLETARE",IF(AND(AE29="OK",AF29="OTTIMO"),"PASSA FORTE",IF(AND(AE29="OK",AF29="OK"),"PASSA","SCARTA"))) | AH29: 2026-10-12 | AI29: yahoo
A30: =IF(AD30="","",RANK(AD30,AD$2:AD$67)) | B30: Banco BPM | C30: BAMI.MI | D30: Banca | E30: Finanziario | F30: 14.735 | G30: EUR | H30: 14.735 | I30: 22182.1 | J30: 22182.1 | K30: 1.27 | L30: 1.42879 | M30: =IF(OR(F30="",K30="",K30<=0),"",F30/K30) | N30: 1.4202409 | O30: =IF(OR(N30="",M30="",M30<=0),"",N30/M30) | P30: 0.12613 | Q30: 0.10212113 | R30: 0.033509752 | S30: 4 | U30: 0.13428123 | V30: 0.13149825 | W30: 0.090072996 | X30: 0.052632052 | Y30: 1 | Z30: =IF(OR(Y30="",F30="",F30=0),"",Y30/F30) | AB30: -0.055 | AC30: 0.29035565 | AD30: =IF(OR(Q30="",M30="",M30<=0),"",ROUND(40*MAX(0,MIN(N(Q30)/0.3,1))+IF(OR(R30="",N(Q30)<=0),10,20*MAX(0,1-MIN(R30/Q30,1)))+30*MAX(0,MIN((PARAMETRI!$B$5-M30)/MAX(PARAMETRI!$B$5-10,1),1))+IF(AB30="",3,10*MAX(0,MIN(AB30/0.15,1)))+IF(AND(P30<>"",N(P30)<N(Q30)*0.6),-8,0),1)) | AE30: =IF(AND(P30="",Q30=""),"DATI MANCANTI",IF(AND(N(P30)>=PARAMETRI!$B$4,N(Q30)>=PARAMETRI!$B$4),"OK","NO")) | AF30: =IF(M30="","N/D",IF(M30<PARAMETRI!$B$6,"OTTIMO",IF(M30<PARAMETRI!$B$5,"OK","NO"))) | AG30: =IF(OR(AE30="DATI MANCANTI",AF30="N/D"),"DA COMPLETARE",IF(AND(AE30="OK",AF30="OTTIMO"),"PASSA FORTE",IF(AND(AE30="OK",AF30="OK"),"PASSA","SCARTA"))) | AH30: 2026-10-09 | AI30: yahoo
A31: =IF(AD31="","",RANK(AD31,AD$2:AD$67)) | B31: Terna | C31: TRN.MI | D31: Utility / Reti | E31: Utility | F31: 9.174 | G31: EUR | H31: 9.174 | I31: 18399.1 | J31: 18399.1 | K31: 0.51 | L31: 0.55945 | M31: =IF(OR(F31="",K31="",K31<=0),"",F31/K31) | N31: 3.0951416 | O31: =IF(OR(N31="",M31="",M31<=0),"",N31/M31) | P31: 0.13828 | Q31: 0.14731665 | R31: 0.012305617 | S31: 4 | V31: 0.14113128 | W31: 0.13999747 | X31: 0.1395311 | Y31: 0.4 | Z31: =IF(OR(Y31="",F31="",F31=0),"",Y31/F31) | AA31: 172.37 | AB31: 0.123 | AC31: 0.29185489 | AD31: =IF(OR(Q31="",M31="",M31<=0),"",ROUND(40*MAX(0,MIN(N(Q31)/0.3,1))+IF(OR(R31="",N(Q31)<=0),10,20*MAX(0,1-MIN(R31/Q31,1)))+30*MAX(0,MIN((PARAMETRI!$B$5-M31)/MAX(PARAMETRI!$B$5-10,1),1))+IF(AB31="",3,10*MAX(0,MIN(AB31/0.15,1)))+IF(AND(P31<>"",N(P31)<N(Q31)*0.6),-8,0),1)) | AE31: =IF(AND(P31="",Q31=""),"DATI MANCANTI",IF(AND(N(P31)>=PARAMETRI!$B$4,N(Q31)>=PARAMETRI!$B$4),"OK","NO")) | AF31: =IF(M31="","N/D",IF(M31<PARAMETRI!$B$6,"OTTIMO",IF(M31<PARAMETRI!$B$5,"OK","NO"))) | AG31: =IF(OR(AE31="DATI MANCANTI",AF31="N/D"),"DA COMPLETARE",IF(AND(AE31="OK",AF31="OTTIMO"),"PASSA FORTE",IF(AND(AE31="OK",AF31="OK"),"PASSA","SCARTA"))) | AH31: 2026-10-12 | AI31: yahoo
A32: =IF(AD32="","",RANK(AD32,AD$2:AD$67)) | B32: MFE-MediaForEurope B | C32: MFEB.MI | D32: Media / TV | E32: Industriale | F32: 2.78 | G32: EUR | H32: 2.78 | I32: 1945 | J32: 1945 | K32: 0.19 | L32: 0.5222 | M32: =IF(OR(F32="",K32="",K32<=0),"",F32/K32) | N32: 0.558345 | O32: =IF(OR(N32="",M32="",M32<=0),"",N32/M32) | P32: 0.055760004 | Q32: 0.072151633 | R32: 0.014705008 | S32: 4 | U32: 0.086321229 | V32: 0.048070555 | W32: 0.072914851 | X32: 0.081299899 | Y32: 0.22 | Z32: =IF(OR(Y32="",F32="",F32=0),"",Y32/F32) | AA32: 88.622 | AB32: 0.945 | AC32: 0.04109692 | AD32: =IF(OR(Q32="",M32="",M32<=0),"",ROUND(40*MAX(0,MIN(N(Q32)/0.3,1))+IF(OR(R32="",N(Q32)<=0),10,20*MAX(0,1-MIN(R32/Q32,1)))+30*MAX(0,MIN((PARAMETRI!$B$5-M32)/MAX(PARAMETRI!$B$5-10,1),1))+IF(AB32="",3,10*MAX(0,MIN(AB32/0.15,1)))+IF(AND(P32<>"",N(P32)<N(Q32)*0.6),-8,0),1)) | AE32: =IF(AND(P32="",Q32=""),"DATI MANCANTI",IF(AND(N(P32)>=PARAMETRI!$B$4,N(Q32)>=PARAMETRI!$B$4),"OK","NO")) | AF32: =IF(M32="","N/D",IF(M32<PARAMETRI!$B$6,"OTTIMO",IF(M32<PARAMETRI!$B$5,"OK","NO"))) | AG32: =IF(OR(AE32="DATI MANCANTI",AF32="N/D"),"DA COMPLETARE",IF(AND(AE32="OK",AF32="OTTIMO"),"PASSA FORTE",IF(AND(AE32="OK",AF32="OK"),"PASSA","SCARTA"))) | AH32: 2026-10-12 | AI32: yahoo | AJ32: Stessa societa' di MFEA, voto multiplo
A33: =IF(AD33="","",RANK(AD33,AD$2:AD$67)) | B33: Pirelli & C. | C33: PIRC.MI | D33: Componentistica auto | E33: Industriale | F33: 6.63 | G33: EUR | H33: 6.63 | I33: 7192.8 | J33: 7192.8 | K33: 0.5 | L33: 0.57562 | M33: =IF(OR(F33="",K33="",K33<=0),"",F33/K33) | N33: 1.1244912 | O33: =IF(OR(N33="",M33="",M33<=0),"",N33/M33) | P33: 0.09134 | Q33: 0.081554515 | R33: 0.0034164553 | S33: 4 | U33: 0.079251202 | V33: 0.081302159 | W33: 0.087194345 | X33: 0.078470354 | Y33: 0.24 | Z33: =IF(OR(Y33="",F33="",F33=0),"",Y33/F33) | AA33: 46.887 | AB33: 0.005 | AC33: 0.076365579 | AD33: =IF(OR(Q33="",M33="",M33<=0),"",ROUND(40*MAX(0,MIN(N(Q33)/0.3,1))+IF(OR(R33="",N(Q33)<=0),10,20*MAX(0,1-MIN(R33/Q33,1)))+30*MAX(0,MIN((PARAMETRI!$B$5-M33)/MAX(PARAMETRI!$B$5-10,1),1))+IF(AB33="",3,10*MAX(0,MIN(AB33/0.15,1)))+IF(AND(P33<>"",N(P33)<N(Q33)*0.6),-8,0),1)) | AE33: =IF(AND(P33="",Q33=""),"DATI MANCANTI",IF(AND(N(P33)>=PARAMETRI!$B$4,N(Q33)>=PARAMETRI!$B$4),"OK","NO")) | AF33: =IF(M33="","N/D",IF(M33<PARAMETRI!$B$6,"OTTIMO",IF(M33<PARAMETRI!$B$5,"OK","NO"))) | AG33: =IF(OR(AE33="DATI MANCANTI",AF33="N/D"),"DA COMPLETARE",IF(AND(AE33="OK",AF33="OTTIMO"),"PASSA FORTE",IF(AND(AE33="OK",AF33="OK"),"PASSA","SCARTA"))) | AH33: 2026-10-12 | AI33: yahoo
